{
 "cells": [
  {
   "cell_type": "code",
   "execution_count": 5,
   "metadata": {},
   "outputs": [],
   "source": [
    "# Dependencies\n",
    "import numpy as np\n",
    "import tweepy\n",
    "import time\n",
    "import json\n",
    "import pandas as pd\n",
    "import queue\n",
    "from requests_toolbelt.threaded import pool\n",
    "\n",
    "# Twitter API Keys\n",
    "# consumer_key = \"TEs2QmTsz4ylhWSqXWHOvVn99\"\n",
    "# consumer_secret = \"yA5M95uhTdeAKLondYQ9LDMPR5LWKc6wX70Yry1oRDHWtBN7gg\"\n",
    "# access_token = \"400199431-wb53H1jfbkDwY0xVS9aZbgWZrWlXcWkhXdFuBKMh\"\n",
    "# access_token_secret = \"IRvQVov2vmopxjeTutR0jn57lnMlYtr8syHQrGbLgbmW9\"\n",
    "\n",
    "consumer_key = \"PAmpYOq5LwscMnRSFBQqwNjxH\"\n",
    "consumer_secret = \"uvvEfLcCoU9zBsRwc3wbWNGwUy7BUVtYH3376MHpLDy7oZ6qUK\"\n",
    "access_token = \"907734237478080523-BAtPF5z8EzzwyPef0f04JC12LOQSCim\"\n",
    "access_token_secret = \"0F5xIDmAwVAy7pQcOWs0mMFDedr9po1tLJuLNk8r3gMuG\"\n",
    "\n",
    "# Twitter Credentials\n",
    "auth = tweepy.OAuthHandler(consumer_key, consumer_secret)\n",
    "auth.set_access_token(access_token, access_token_secret)\n",
    "api = tweepy.API(auth, parser=tweepy.parsers.JSONParser(), wait_on_rate_limit = True, wait_on_rate_limit_notify = True)\n"
   ]
  },
  {
   "cell_type": "code",
   "execution_count": 6,
   "metadata": {},
   "outputs": [
    {
     "data": {
      "text/html": [
       "<div>\n",
       "<style>\n",
       "    .dataframe thead tr:only-child th {\n",
       "        text-align: right;\n",
       "    }\n",
       "\n",
       "    .dataframe thead th {\n",
       "        text-align: left;\n",
       "    }\n",
       "\n",
       "    .dataframe tbody tr th {\n",
       "        vertical-align: top;\n",
       "    }\n",
       "</style>\n",
       "<table border=\"1\" class=\"dataframe\">\n",
       "  <thead>\n",
       "    <tr style=\"text-align: right;\">\n",
       "      <th></th>\n",
       "      <th>lat</th>\n",
       "      <th>lon</th>\n",
       "    </tr>\n",
       "    <tr>\n",
       "      <th>State</th>\n",
       "      <th></th>\n",
       "      <th></th>\n",
       "    </tr>\n",
       "  </thead>\n",
       "  <tbody>\n",
       "    <tr>\n",
       "      <th>Alabama</th>\n",
       "      <td>32.886361</td>\n",
       "      <td>-86.813639</td>\n",
       "    </tr>\n",
       "    <tr>\n",
       "      <th>Alaska</th>\n",
       "      <td>61.456423</td>\n",
       "      <td>-152.486981</td>\n",
       "    </tr>\n",
       "    <tr>\n",
       "      <th>Arizona</th>\n",
       "      <td>33.610082</td>\n",
       "      <td>-111.647927</td>\n",
       "    </tr>\n",
       "    <tr>\n",
       "      <th>Arkansas</th>\n",
       "      <td>35.124723</td>\n",
       "      <td>-92.402676</td>\n",
       "    </tr>\n",
       "    <tr>\n",
       "      <th>California</th>\n",
       "      <td>36.170738</td>\n",
       "      <td>-119.792701</td>\n",
       "    </tr>\n",
       "    <tr>\n",
       "      <th>Colorado</th>\n",
       "      <td>39.264176</td>\n",
       "      <td>-105.317544</td>\n",
       "    </tr>\n",
       "    <tr>\n",
       "      <th>Connecticut</th>\n",
       "      <td>41.563130</td>\n",
       "      <td>-72.804928</td>\n",
       "    </tr>\n",
       "    <tr>\n",
       "      <th>Delaware</th>\n",
       "      <td>39.300372</td>\n",
       "      <td>-75.526776</td>\n",
       "    </tr>\n",
       "    <tr>\n",
       "      <th>District of Columbia</th>\n",
       "      <td>38.896231</td>\n",
       "      <td>-77.021235</td>\n",
       "    </tr>\n",
       "    <tr>\n",
       "      <th>Florida</th>\n",
       "      <td>28.129716</td>\n",
       "      <td>-81.956165</td>\n",
       "    </tr>\n",
       "  </tbody>\n",
       "</table>\n",
       "</div>"
      ],
      "text/plain": [
       "                            lat         lon\n",
       "State                                      \n",
       "Alabama               32.886361  -86.813639\n",
       "Alaska                61.456423 -152.486981\n",
       "Arizona               33.610082 -111.647927\n",
       "Arkansas              35.124723  -92.402676\n",
       "California            36.170738 -119.792701\n",
       "Colorado              39.264176 -105.317544\n",
       "Connecticut           41.563130  -72.804928\n",
       "Delaware              39.300372  -75.526776\n",
       "District of Columbia  38.896231  -77.021235\n",
       "Florida               28.129716  -81.956165"
      ]
     },
     "execution_count": 6,
     "metadata": {},
     "output_type": "execute_result"
    }
   ],
   "source": [
    "# Get a list of locations in and outside the belt (in-belt, out-belt)\n",
    "base_data = pd.read_csv(\"Zipcode_States_With_Geo_Cordinates.csv\")\n",
    "lat = base_data.groupby(\"State\")[\"Latitude\"].mean()\n",
    "lon = base_data.groupby(\"State\")[\"Longitude\"].mean()\n",
    "dfff = {\"lat\":[], \"lon\":[]}\n",
    "for each in lat.index:\n",
    "    dfff[\"lat\"].append(lat[each])\n",
    "    dfff[\"lon\"].append(lon[each])\n",
    "hah = pd.DataFrame(dfff)\n",
    "base_data_state = hah.set_index([lat.index])\n",
    "\n",
    "base_data_state.head(10)"
   ]
  },
  {
   "cell_type": "code",
   "execution_count": 7,
   "metadata": {},
   "outputs": [
    {
     "data": {
      "text/html": [
       "<div>\n",
       "<style>\n",
       "    .dataframe thead tr:only-child th {\n",
       "        text-align: right;\n",
       "    }\n",
       "\n",
       "    .dataframe thead th {\n",
       "        text-align: left;\n",
       "    }\n",
       "\n",
       "    .dataframe tbody tr th {\n",
       "        vertical-align: top;\n",
       "    }\n",
       "</style>\n",
       "<table border=\"1\" class=\"dataframe\">\n",
       "  <thead>\n",
       "    <tr style=\"text-align: right;\">\n",
       "      <th></th>\n",
       "      <th>State</th>\n",
       "      <th>lat</th>\n",
       "      <th>lon</th>\n",
       "    </tr>\n",
       "  </thead>\n",
       "  <tbody>\n",
       "    <tr>\n",
       "      <th>0</th>\n",
       "      <td>Alabama</td>\n",
       "      <td>32.886361</td>\n",
       "      <td>-86.813639</td>\n",
       "    </tr>\n",
       "    <tr>\n",
       "      <th>1</th>\n",
       "      <td>Alaska</td>\n",
       "      <td>61.456423</td>\n",
       "      <td>-152.486981</td>\n",
       "    </tr>\n",
       "    <tr>\n",
       "      <th>2</th>\n",
       "      <td>Arizona</td>\n",
       "      <td>33.610082</td>\n",
       "      <td>-111.647927</td>\n",
       "    </tr>\n",
       "    <tr>\n",
       "      <th>3</th>\n",
       "      <td>Arkansas</td>\n",
       "      <td>35.124723</td>\n",
       "      <td>-92.402676</td>\n",
       "    </tr>\n",
       "    <tr>\n",
       "      <th>4</th>\n",
       "      <td>California</td>\n",
       "      <td>36.170738</td>\n",
       "      <td>-119.792701</td>\n",
       "    </tr>\n",
       "    <tr>\n",
       "      <th>5</th>\n",
       "      <td>Colorado</td>\n",
       "      <td>39.264176</td>\n",
       "      <td>-105.317544</td>\n",
       "    </tr>\n",
       "    <tr>\n",
       "      <th>6</th>\n",
       "      <td>Connecticut</td>\n",
       "      <td>41.563130</td>\n",
       "      <td>-72.804928</td>\n",
       "    </tr>\n",
       "    <tr>\n",
       "      <th>7</th>\n",
       "      <td>Delaware</td>\n",
       "      <td>39.300372</td>\n",
       "      <td>-75.526776</td>\n",
       "    </tr>\n",
       "    <tr>\n",
       "      <th>8</th>\n",
       "      <td>District of Columbia</td>\n",
       "      <td>38.896231</td>\n",
       "      <td>-77.021235</td>\n",
       "    </tr>\n",
       "    <tr>\n",
       "      <th>9</th>\n",
       "      <td>Florida</td>\n",
       "      <td>28.129716</td>\n",
       "      <td>-81.956165</td>\n",
       "    </tr>\n",
       "    <tr>\n",
       "      <th>10</th>\n",
       "      <td>Georgia</td>\n",
       "      <td>33.039353</td>\n",
       "      <td>-83.703548</td>\n",
       "    </tr>\n",
       "    <tr>\n",
       "      <th>11</th>\n",
       "      <td>Hawaii</td>\n",
       "      <td>20.982851</td>\n",
       "      <td>-154.974506</td>\n",
       "    </tr>\n",
       "    <tr>\n",
       "      <th>12</th>\n",
       "      <td>Idaho</td>\n",
       "      <td>44.528701</td>\n",
       "      <td>-114.823182</td>\n",
       "    </tr>\n",
       "    <tr>\n",
       "      <th>13</th>\n",
       "      <td>Illinois</td>\n",
       "      <td>40.431630</td>\n",
       "      <td>-88.982426</td>\n",
       "    </tr>\n",
       "    <tr>\n",
       "      <th>14</th>\n",
       "      <td>Indiana</td>\n",
       "      <td>39.940257</td>\n",
       "      <td>-86.267798</td>\n",
       "    </tr>\n",
       "    <tr>\n",
       "      <th>15</th>\n",
       "      <td>Iowa</td>\n",
       "      <td>42.023004</td>\n",
       "      <td>-93.333375</td>\n",
       "    </tr>\n",
       "    <tr>\n",
       "      <th>16</th>\n",
       "      <td>Kansas</td>\n",
       "      <td>38.512026</td>\n",
       "      <td>-97.158466</td>\n",
       "    </tr>\n",
       "    <tr>\n",
       "      <th>17</th>\n",
       "      <td>Kentucky</td>\n",
       "      <td>37.618760</td>\n",
       "      <td>-84.832041</td>\n",
       "    </tr>\n",
       "    <tr>\n",
       "      <th>18</th>\n",
       "      <td>Louisiana</td>\n",
       "      <td>30.935336</td>\n",
       "      <td>-91.744272</td>\n",
       "    </tr>\n",
       "    <tr>\n",
       "      <th>19</th>\n",
       "      <td>Maine</td>\n",
       "      <td>44.568311</td>\n",
       "      <td>-69.430814</td>\n",
       "    </tr>\n",
       "    <tr>\n",
       "      <th>20</th>\n",
       "      <td>Maryland</td>\n",
       "      <td>39.054627</td>\n",
       "      <td>-76.781291</td>\n",
       "    </tr>\n",
       "    <tr>\n",
       "      <th>21</th>\n",
       "      <td>Massachusetts</td>\n",
       "      <td>42.235230</td>\n",
       "      <td>-71.494505</td>\n",
       "    </tr>\n",
       "    <tr>\n",
       "      <th>22</th>\n",
       "      <td>Michigan</td>\n",
       "      <td>43.443537</td>\n",
       "      <td>-84.735522</td>\n",
       "    </tr>\n",
       "    <tr>\n",
       "      <th>23</th>\n",
       "      <td>Minnesota</td>\n",
       "      <td>45.563066</td>\n",
       "      <td>-94.122988</td>\n",
       "    </tr>\n",
       "    <tr>\n",
       "      <th>24</th>\n",
       "      <td>Mississippi</td>\n",
       "      <td>32.826760</td>\n",
       "      <td>-89.691043</td>\n",
       "    </tr>\n",
       "    <tr>\n",
       "      <th>25</th>\n",
       "      <td>Missouri</td>\n",
       "      <td>38.393612</td>\n",
       "      <td>-92.464955</td>\n",
       "    </tr>\n",
       "    <tr>\n",
       "      <th>26</th>\n",
       "      <td>Montana</td>\n",
       "      <td>46.937847</td>\n",
       "      <td>-110.300981</td>\n",
       "    </tr>\n",
       "    <tr>\n",
       "      <th>27</th>\n",
       "      <td>Nebraska</td>\n",
       "      <td>41.191139</td>\n",
       "      <td>-98.152799</td>\n",
       "    </tr>\n",
       "    <tr>\n",
       "      <th>28</th>\n",
       "      <td>Nevada</td>\n",
       "      <td>37.829281</td>\n",
       "      <td>-116.636755</td>\n",
       "    </tr>\n",
       "    <tr>\n",
       "      <th>29</th>\n",
       "      <td>New Hampshire</td>\n",
       "      <td>43.388981</td>\n",
       "      <td>-71.566260</td>\n",
       "    </tr>\n",
       "    <tr>\n",
       "      <th>30</th>\n",
       "      <td>New Jersey</td>\n",
       "      <td>40.385105</td>\n",
       "      <td>-74.517176</td>\n",
       "    </tr>\n",
       "    <tr>\n",
       "      <th>31</th>\n",
       "      <td>New Mexico</td>\n",
       "      <td>34.695231</td>\n",
       "      <td>-106.171181</td>\n",
       "    </tr>\n",
       "    <tr>\n",
       "      <th>32</th>\n",
       "      <td>New York</td>\n",
       "      <td>42.224909</td>\n",
       "      <td>-75.145666</td>\n",
       "    </tr>\n",
       "    <tr>\n",
       "      <th>33</th>\n",
       "      <td>North Carolina</td>\n",
       "      <td>35.573293</td>\n",
       "      <td>-79.527942</td>\n",
       "    </tr>\n",
       "    <tr>\n",
       "      <th>34</th>\n",
       "      <td>North Dakota</td>\n",
       "      <td>47.511215</td>\n",
       "      <td>-99.611182</td>\n",
       "    </tr>\n",
       "    <tr>\n",
       "      <th>35</th>\n",
       "      <td>Ohio</td>\n",
       "      <td>40.387888</td>\n",
       "      <td>-82.738925</td>\n",
       "    </tr>\n",
       "    <tr>\n",
       "      <th>36</th>\n",
       "      <td>Oklahoma</td>\n",
       "      <td>35.511279</td>\n",
       "      <td>-97.001071</td>\n",
       "    </tr>\n",
       "    <tr>\n",
       "      <th>37</th>\n",
       "      <td>Oregon</td>\n",
       "      <td>44.523446</td>\n",
       "      <td>-122.083470</td>\n",
       "    </tr>\n",
       "    <tr>\n",
       "      <th>38</th>\n",
       "      <td>Pennsylvania</td>\n",
       "      <td>40.620174</td>\n",
       "      <td>-77.561971</td>\n",
       "    </tr>\n",
       "    <tr>\n",
       "      <th>39</th>\n",
       "      <td>Rhode Island</td>\n",
       "      <td>41.708033</td>\n",
       "      <td>-71.501928</td>\n",
       "    </tr>\n",
       "    <tr>\n",
       "      <th>40</th>\n",
       "      <td>South Carolina</td>\n",
       "      <td>33.959091</td>\n",
       "      <td>-81.052546</td>\n",
       "    </tr>\n",
       "    <tr>\n",
       "      <th>41</th>\n",
       "      <td>South Dakota</td>\n",
       "      <td>44.300723</td>\n",
       "      <td>-99.122511</td>\n",
       "    </tr>\n",
       "    <tr>\n",
       "      <th>42</th>\n",
       "      <td>Tennessee</td>\n",
       "      <td>35.806470</td>\n",
       "      <td>-86.431453</td>\n",
       "    </tr>\n",
       "    <tr>\n",
       "      <th>43</th>\n",
       "      <td>Texas</td>\n",
       "      <td>31.271336</td>\n",
       "      <td>-98.000057</td>\n",
       "    </tr>\n",
       "    <tr>\n",
       "      <th>44</th>\n",
       "      <td>Utah</td>\n",
       "      <td>39.908996</td>\n",
       "      <td>-111.831077</td>\n",
       "    </tr>\n",
       "    <tr>\n",
       "      <th>45</th>\n",
       "      <td>Vermont</td>\n",
       "      <td>44.033687</td>\n",
       "      <td>-72.650105</td>\n",
       "    </tr>\n",
       "    <tr>\n",
       "      <th>46</th>\n",
       "      <td>Virginia</td>\n",
       "      <td>37.714253</td>\n",
       "      <td>-78.228202</td>\n",
       "    </tr>\n",
       "    <tr>\n",
       "      <th>47</th>\n",
       "      <td>Washington</td>\n",
       "      <td>47.346199</td>\n",
       "      <td>-121.220077</td>\n",
       "    </tr>\n",
       "    <tr>\n",
       "      <th>48</th>\n",
       "      <td>West Virginia</td>\n",
       "      <td>38.485682</td>\n",
       "      <td>-80.976803</td>\n",
       "    </tr>\n",
       "    <tr>\n",
       "      <th>49</th>\n",
       "      <td>Wisconsin</td>\n",
       "      <td>44.109156</td>\n",
       "      <td>-89.534600</td>\n",
       "    </tr>\n",
       "    <tr>\n",
       "      <th>50</th>\n",
       "      <td>Wyoming</td>\n",
       "      <td>42.860294</td>\n",
       "      <td>-107.296522</td>\n",
       "    </tr>\n",
       "  </tbody>\n",
       "</table>\n",
       "</div>"
      ],
      "text/plain": [
       "                   State        lat         lon\n",
       "0                Alabama  32.886361  -86.813639\n",
       "1                 Alaska  61.456423 -152.486981\n",
       "2                Arizona  33.610082 -111.647927\n",
       "3               Arkansas  35.124723  -92.402676\n",
       "4             California  36.170738 -119.792701\n",
       "5               Colorado  39.264176 -105.317544\n",
       "6            Connecticut  41.563130  -72.804928\n",
       "7               Delaware  39.300372  -75.526776\n",
       "8   District of Columbia  38.896231  -77.021235\n",
       "9                Florida  28.129716  -81.956165\n",
       "10               Georgia  33.039353  -83.703548\n",
       "11                Hawaii  20.982851 -154.974506\n",
       "12                 Idaho  44.528701 -114.823182\n",
       "13              Illinois  40.431630  -88.982426\n",
       "14               Indiana  39.940257  -86.267798\n",
       "15                  Iowa  42.023004  -93.333375\n",
       "16                Kansas  38.512026  -97.158466\n",
       "17              Kentucky  37.618760  -84.832041\n",
       "18             Louisiana  30.935336  -91.744272\n",
       "19                 Maine  44.568311  -69.430814\n",
       "20              Maryland  39.054627  -76.781291\n",
       "21         Massachusetts  42.235230  -71.494505\n",
       "22              Michigan  43.443537  -84.735522\n",
       "23             Minnesota  45.563066  -94.122988\n",
       "24           Mississippi  32.826760  -89.691043\n",
       "25              Missouri  38.393612  -92.464955\n",
       "26               Montana  46.937847 -110.300981\n",
       "27              Nebraska  41.191139  -98.152799\n",
       "28                Nevada  37.829281 -116.636755\n",
       "29         New Hampshire  43.388981  -71.566260\n",
       "30            New Jersey  40.385105  -74.517176\n",
       "31            New Mexico  34.695231 -106.171181\n",
       "32              New York  42.224909  -75.145666\n",
       "33        North Carolina  35.573293  -79.527942\n",
       "34          North Dakota  47.511215  -99.611182\n",
       "35                  Ohio  40.387888  -82.738925\n",
       "36              Oklahoma  35.511279  -97.001071\n",
       "37                Oregon  44.523446 -122.083470\n",
       "38          Pennsylvania  40.620174  -77.561971\n",
       "39          Rhode Island  41.708033  -71.501928\n",
       "40        South Carolina  33.959091  -81.052546\n",
       "41          South Dakota  44.300723  -99.122511\n",
       "42             Tennessee  35.806470  -86.431453\n",
       "43                 Texas  31.271336  -98.000057\n",
       "44                  Utah  39.908996 -111.831077\n",
       "45               Vermont  44.033687  -72.650105\n",
       "46              Virginia  37.714253  -78.228202\n",
       "47            Washington  47.346199 -121.220077\n",
       "48         West Virginia  38.485682  -80.976803\n",
       "49             Wisconsin  44.109156  -89.534600\n",
       "50               Wyoming  42.860294 -107.296522"
      ]
     },
     "execution_count": 7,
     "metadata": {},
     "output_type": "execute_result"
    }
   ],
   "source": [
    "base_data_state = base_data_state.reset_index()\n",
    "base_data_state"
   ]
  },
  {
   "cell_type": "code",
   "execution_count": 8,
   "metadata": {},
   "outputs": [
    {
     "data": {
      "text/html": [
       "<div>\n",
       "<style>\n",
       "    .dataframe thead tr:only-child th {\n",
       "        text-align: right;\n",
       "    }\n",
       "\n",
       "    .dataframe thead th {\n",
       "        text-align: left;\n",
       "    }\n",
       "\n",
       "    .dataframe tbody tr th {\n",
       "        vertical-align: top;\n",
       "    }\n",
       "</style>\n",
       "<table border=\"1\" class=\"dataframe\">\n",
       "  <thead>\n",
       "    <tr style=\"text-align: right;\">\n",
       "      <th></th>\n",
       "      <th>state</th>\n",
       "      <th>text</th>\n",
       "      <th>lat</th>\n",
       "      <th>lon</th>\n",
       "      <th>followers</th>\n",
       "      <th>favorites</th>\n",
       "      <th>friends</th>\n",
       "      <th>statuses_count</th>\n",
       "      <th>compound</th>\n",
       "      <th>pos</th>\n",
       "      <th>neg</th>\n",
       "    </tr>\n",
       "  </thead>\n",
       "  <tbody>\n",
       "  </tbody>\n",
       "</table>\n",
       "</div>"
      ],
      "text/plain": [
       "Empty DataFrame\n",
       "Columns: [state, text, lat, lon, followers, favorites, friends, statuses_count, compound, pos, neg]\n",
       "Index: []"
      ]
     },
     "execution_count": 8,
     "metadata": {},
     "output_type": "execute_result"
    }
   ],
   "source": [
    "tweet_df = {}\n",
    "tweet_df = pd.DataFrame(tweet_df)\n",
    "tweet_df[\"state\"] = \"\"\n",
    "tweet_df[\"text\"] = \"\"\n",
    "tweet_df[\"lat\"] = \"\"\n",
    "tweet_df[\"lon\"] = \"\"\n",
    "tweet_df[\"followers\"] = \"\"\n",
    "tweet_df[\"favorites\"] = \"\"\n",
    "tweet_df[\"friends\"] = \"\"\n",
    "tweet_df[\"statuses_count\"] = \"\"\n",
    "tweet_df[\"compound\"] = \"\"\n",
    "tweet_df[\"pos\"] = \"\"\n",
    "tweet_df[\"neg\"] = \"\"\n",
    "\n",
    "\n",
    "tweet_df.head()\n"
   ]
  },
  {
   "cell_type": "code",
   "execution_count": 9,
   "metadata": {},
   "outputs": [
    {
     "name": "stderr",
     "output_type": "stream",
     "text": [
      "Exception in thread 7efee40b-ef3e-4fc9-92ec-2edcf84dadbb:\n",
      "Traceback (most recent call last):\n",
      "  File \"/Users/Me/anaconda/envs/PythonData/lib/python3.6/site-packages/requests_toolbelt/threaded/thread.py\", line 30, in _handle_request\n",
      "    response = self._session.request(**kwargs)\n",
      "  File \"/Users/Me/anaconda/envs/PythonData/lib/python3.6/site-packages/requests/sessions.py\", line 504, in request\n",
      "    prep = self.prepare_request(req)\n",
      "  File \"/Users/Me/anaconda/envs/PythonData/lib/python3.6/site-packages/requests/sessions.py\", line 436, in prepare_request\n",
      "    hooks=merge_hooks(request.hooks, self.hooks),\n",
      "  File \"/Users/Me/anaconda/envs/PythonData/lib/python3.6/site-packages/requests/models.py\", line 302, in prepare\n",
      "    self.prepare_url(url, params)\n",
      "  File \"/Users/Me/anaconda/envs/PythonData/lib/python3.6/site-packages/requests/models.py\", line 382, in prepare_url\n",
      "    raise MissingSchema(error)\n",
      "requests.exceptions.MissingSchema: Invalid URL 'statuses': No schema supplied. Perhaps you meant http://statuses?\n",
      "\n",
      "During handling of the above exception, another exception occurred:\n",
      "\n",
      "Traceback (most recent call last):\n",
      "  File \"/Users/Me/anaconda/envs/PythonData/lib/python3.6/threading.py\", line 916, in _bootstrap_inner\n",
      "    self.run()\n",
      "  File \"/Users/Me/anaconda/envs/PythonData/lib/python3.6/threading.py\", line 864, in run\n",
      "    self._target(*self._args, **self._kwargs)\n",
      "  File \"/Users/Me/anaconda/envs/PythonData/lib/python3.6/site-packages/requests_toolbelt/threaded/thread.py\", line 45, in _make_request\n",
      "    self._handle_request(kwargs)\n",
      "  File \"/Users/Me/anaconda/envs/PythonData/lib/python3.6/site-packages/requests_toolbelt/threaded/thread.py\", line 32, in _handle_request\n",
      "    self._exceptions.put((kwargs, e))\n",
      "AttributeError: 'SessionThread' object has no attribute '_exceptions'\n",
      "Exception in thread 592797b7-24fe-44c2-8f30-0ccff508b119:\n",
      "Traceback (most recent call last):\n",
      "  File \"/Users/Me/anaconda/envs/PythonData/lib/python3.6/site-packages/requests_toolbelt/threaded/thread.py\", line 30, in _handle_request\n",
      "    response = self._session.request(**kwargs)\n",
      "  File \"/Users/Me/anaconda/envs/PythonData/lib/python3.6/site-packages/requests/sessions.py\", line 504, in request\n",
      "    prep = self.prepare_request(req)\n",
      "  File \"/Users/Me/anaconda/envs/PythonData/lib/python3.6/site-packages/requests/sessions.py\", line 436, in prepare_request\n",
      "    hooks=merge_hooks(request.hooks, self.hooks),\n",
      "  File \"/Users/Me/anaconda/envs/PythonData/lib/python3.6/site-packages/requests/models.py\", line 302, in prepare\n",
      "    self.prepare_url(url, params)\n",
      "  File \"/Users/Me/anaconda/envs/PythonData/lib/python3.6/site-packages/requests/models.py\", line 382, in prepare_url\n",
      "    raise MissingSchema(error)\n",
      "requests.exceptions.MissingSchema: Invalid URL 'search_metadata': No schema supplied. Perhaps you meant http://search_metadata?\n",
      "\n",
      "During handling of the above exception, another exception occurred:\n",
      "\n",
      "Traceback (most recent call last):\n",
      "  File \"/Users/Me/anaconda/envs/PythonData/lib/python3.6/threading.py\", line 916, in _bootstrap_inner\n",
      "    self.run()\n",
      "  File \"/Users/Me/anaconda/envs/PythonData/lib/python3.6/threading.py\", line 864, in run\n",
      "    self._target(*self._args, **self._kwargs)\n",
      "  File \"/Users/Me/anaconda/envs/PythonData/lib/python3.6/site-packages/requests_toolbelt/threaded/thread.py\", line 45, in _make_request\n",
      "    self._handle_request(kwargs)\n",
      "  File \"/Users/Me/anaconda/envs/PythonData/lib/python3.6/site-packages/requests_toolbelt/threaded/thread.py\", line 32, in _handle_request\n",
      "    self._exceptions.put((kwargs, e))\n",
      "AttributeError: 'SessionThread' object has no attribute '_exceptions'\n",
      "\n",
      "\n",
      "Exception in thread aed34cf0-0421-488e-a0ea-0437b66b9565:\n",
      "Traceback (most recent call last):\n",
      "  File \"/Users/Me/anaconda/envs/PythonData/lib/python3.6/site-packages/requests_toolbelt/threaded/thread.py\", line 30, in _handle_request\n",
      "    response = self._session.request(**kwargs)\n",
      "  File \"/Users/Me/anaconda/envs/PythonData/lib/python3.6/site-packages/requests/sessions.py\", line 504, in request\n",
      "    prep = self.prepare_request(req)\n",
      "  File \"/Users/Me/anaconda/envs/PythonData/lib/python3.6/site-packages/requests/sessions.py\", line 436, in prepare_request\n",
      "    hooks=merge_hooks(request.hooks, self.hooks),\n",
      "  File \"/Users/Me/anaconda/envs/PythonData/lib/python3.6/site-packages/requests/models.py\", line 302, in prepare\n",
      "    self.prepare_url(url, params)\n",
      "  File \"/Users/Me/anaconda/envs/PythonData/lib/python3.6/site-packages/requests/models.py\", line 382, in prepare_url\n",
      "    raise MissingSchema(error)\n",
      "requests.exceptions.MissingSchema: Invalid URL 'statuses': No schema supplied. Perhaps you meant http://statuses?\n",
      "\n",
      "During handling of the above exception, another exception occurred:\n",
      "\n",
      "Traceback (most recent call last):\n",
      "  File \"/Users/Me/anaconda/envs/PythonData/lib/python3.6/threading.py\", line 916, in _bootstrap_inner\n",
      "    self.run()\n",
      "  File \"/Users/Me/anaconda/envs/PythonData/lib/python3.6/threading.py\", line 864, in run\n",
      "    self._target(*self._args, **self._kwargs)\n",
      "  File \"/Users/Me/anaconda/envs/PythonData/lib/python3.6/site-packages/requests_toolbelt/threaded/thread.py\", line 45, in _make_request\n",
      "    self._handle_request(kwargs)\n",
      "  File \"/Users/Me/anaconda/envs/PythonData/lib/python3.6/site-packages/requests_toolbelt/threaded/thread.py\", line 32, in _handle_request\n",
      "    self._exceptions.put((kwargs, e))\n",
      "AttributeError: 'SessionThread' object has no attribute '_exceptions'\n",
      "Exception in thread 0b2aadc0-053c-4dcb-83ae-8b88054e6215:\n",
      "Traceback (most recent call last):\n",
      "  File \"/Users/Me/anaconda/envs/PythonData/lib/python3.6/site-packages/requests_toolbelt/threaded/thread.py\", line 30, in _handle_request\n",
      "    response = self._session.request(**kwargs)\n",
      "  File \"/Users/Me/anaconda/envs/PythonData/lib/python3.6/site-packages/requests/sessions.py\", line 504, in request\n",
      "    prep = self.prepare_request(req)\n",
      "  File \"/Users/Me/anaconda/envs/PythonData/lib/python3.6/site-packages/requests/sessions.py\", line 436, in prepare_request\n",
      "    hooks=merge_hooks(request.hooks, self.hooks),\n",
      "  File \"/Users/Me/anaconda/envs/PythonData/lib/python3.6/site-packages/requests/models.py\", line 302, in prepare\n",
      "    self.prepare_url(url, params)\n",
      "  File \"/Users/Me/anaconda/envs/PythonData/lib/python3.6/site-packages/requests/models.py\", line 382, in prepare_url\n",
      "    raise MissingSchema(error)\n",
      "requests.exceptions.MissingSchema: Invalid URL 'search_metadata': No schema supplied. Perhaps you meant http://search_metadata?\n",
      "\n",
      "During handling of the above exception, another exception occurred:\n",
      "\n",
      "Traceback (most recent call last):\n",
      "  File \"/Users/Me/anaconda/envs/PythonData/lib/python3.6/threading.py\", line 916, in _bootstrap_inner\n",
      "    self.run()\n",
      "  File \"/Users/Me/anaconda/envs/PythonData/lib/python3.6/threading.py\", line 864, in run\n",
      "    self._target(*self._args, **self._kwargs)\n",
      "  File \"/Users/Me/anaconda/envs/PythonData/lib/python3.6/site-packages/requests_toolbelt/threaded/thread.py\", line 45, in _make_request\n",
      "    self._handle_request(kwargs)\n",
      "  File \"/Users/Me/anaconda/envs/PythonData/lib/python3.6/site-packages/requests_toolbelt/threaded/thread.py\", line 32, in _handle_request\n",
      "    self._exceptions.put((kwargs, e))\n",
      "AttributeError: 'SessionThread' object has no attribute '_exceptions'\n",
      "\n",
      "\n",
      "Exception in thread 1854aa93-6395-497e-aa11-cda6b54b96ef:\n",
      "Traceback (most recent call last):\n",
      "  File \"/Users/Me/anaconda/envs/PythonData/lib/python3.6/site-packages/requests_toolbelt/threaded/thread.py\", line 30, in _handle_request\n",
      "    response = self._session.request(**kwargs)\n",
      "  File \"/Users/Me/anaconda/envs/PythonData/lib/python3.6/site-packages/requests/sessions.py\", line 504, in request\n",
      "    prep = self.prepare_request(req)\n",
      "  File \"/Users/Me/anaconda/envs/PythonData/lib/python3.6/site-packages/requests/sessions.py\", line 436, in prepare_request\n",
      "    hooks=merge_hooks(request.hooks, self.hooks),\n",
      "  File \"/Users/Me/anaconda/envs/PythonData/lib/python3.6/site-packages/requests/models.py\", line 302, in prepare\n",
      "    self.prepare_url(url, params)\n",
      "  File \"/Users/Me/anaconda/envs/PythonData/lib/python3.6/site-packages/requests/models.py\", line 382, in prepare_url\n",
      "    raise MissingSchema(error)\n",
      "requests.exceptions.MissingSchema: Invalid URL 'statuses': No schema supplied. Perhaps you meant http://statuses?\n",
      "\n",
      "During handling of the above exception, another exception occurred:\n",
      "\n",
      "Traceback (most recent call last):\n",
      "  File \"/Users/Me/anaconda/envs/PythonData/lib/python3.6/threading.py\", line 916, in _bootstrap_inner\n",
      "    self.run()\n",
      "  File \"/Users/Me/anaconda/envs/PythonData/lib/python3.6/threading.py\", line 864, in run\n",
      "    self._target(*self._args, **self._kwargs)\n",
      "  File \"/Users/Me/anaconda/envs/PythonData/lib/python3.6/site-packages/requests_toolbelt/threaded/thread.py\", line 45, in _make_request\n",
      "    self._handle_request(kwargs)\n",
      "  File \"/Users/Me/anaconda/envs/PythonData/lib/python3.6/site-packages/requests_toolbelt/threaded/thread.py\", line 32, in _handle_request\n",
      "    self._exceptions.put((kwargs, e))\n",
      "AttributeError: 'SessionThread' object has no attribute '_exceptions'\n",
      "\n"
     ]
    },
    {
     "name": "stderr",
     "output_type": "stream",
     "text": [
      "Exception in thread f99f2b32-27fb-4e05-8da1-47051d08ab42:\n",
      "Traceback (most recent call last):\n",
      "  File \"/Users/Me/anaconda/envs/PythonData/lib/python3.6/site-packages/requests_toolbelt/threaded/thread.py\", line 30, in _handle_request\n",
      "    response = self._session.request(**kwargs)\n",
      "  File \"/Users/Me/anaconda/envs/PythonData/lib/python3.6/site-packages/requests/sessions.py\", line 504, in request\n",
      "    prep = self.prepare_request(req)\n",
      "  File \"/Users/Me/anaconda/envs/PythonData/lib/python3.6/site-packages/requests/sessions.py\", line 436, in prepare_request\n",
      "    hooks=merge_hooks(request.hooks, self.hooks),\n",
      "  File \"/Users/Me/anaconda/envs/PythonData/lib/python3.6/site-packages/requests/models.py\", line 302, in prepare\n",
      "    self.prepare_url(url, params)\n",
      "  File \"/Users/Me/anaconda/envs/PythonData/lib/python3.6/site-packages/requests/models.py\", line 382, in prepare_url\n",
      "    raise MissingSchema(error)\n",
      "requests.exceptions.MissingSchema: Invalid URL 'search_metadata': No schema supplied. Perhaps you meant http://search_metadata?\n",
      "\n",
      "During handling of the above exception, another exception occurred:\n",
      "\n",
      "Traceback (most recent call last):\n",
      "  File \"/Users/Me/anaconda/envs/PythonData/lib/python3.6/threading.py\", line 916, in _bootstrap_inner\n",
      "    self.run()\n",
      "  File \"/Users/Me/anaconda/envs/PythonData/lib/python3.6/threading.py\", line 864, in run\n",
      "    self._target(*self._args, **self._kwargs)\n",
      "  File \"/Users/Me/anaconda/envs/PythonData/lib/python3.6/site-packages/requests_toolbelt/threaded/thread.py\", line 45, in _make_request\n",
      "    self._handle_request(kwargs)\n",
      "  File \"/Users/Me/anaconda/envs/PythonData/lib/python3.6/site-packages/requests_toolbelt/threaded/thread.py\", line 32, in _handle_request\n",
      "    self._exceptions.put((kwargs, e))\n",
      "AttributeError: 'SessionThread' object has no attribute '_exceptions'\n",
      "\n",
      "Exception in thread d92f2b32-fc94-494c-ab1b-1d7da439d1a6:\n",
      "Traceback (most recent call last):\n",
      "  File \"/Users/Me/anaconda/envs/PythonData/lib/python3.6/site-packages/requests_toolbelt/threaded/thread.py\", line 30, in _handle_request\n",
      "    response = self._session.request(**kwargs)\n",
      "  File \"/Users/Me/anaconda/envs/PythonData/lib/python3.6/site-packages/requests/sessions.py\", line 504, in request\n",
      "    prep = self.prepare_request(req)\n",
      "  File \"/Users/Me/anaconda/envs/PythonData/lib/python3.6/site-packages/requests/sessions.py\", line 436, in prepare_request\n",
      "    hooks=merge_hooks(request.hooks, self.hooks),\n",
      "  File \"/Users/Me/anaconda/envs/PythonData/lib/python3.6/site-packages/requests/models.py\", line 302, in prepare\n",
      "    self.prepare_url(url, params)\n",
      "  File \"/Users/Me/anaconda/envs/PythonData/lib/python3.6/site-packages/requests/models.py\", line 382, in prepare_url\n",
      "    raise MissingSchema(error)\n",
      "requests.exceptions.MissingSchema: Invalid URL 'search_metadata': No schema supplied. Perhaps you meant http://search_metadata?\n",
      "\n",
      "During handling of the above exception, another exception occurred:\n",
      "\n",
      "Traceback (most recent call last):\n",
      "  File \"/Users/Me/anaconda/envs/PythonData/lib/python3.6/threading.py\", line 916, in _bootstrap_inner\n",
      "    self.run()\n",
      "  File \"/Users/Me/anaconda/envs/PythonData/lib/python3.6/threading.py\", line 864, in run\n",
      "    self._target(*self._args, **self._kwargs)\n",
      "  File \"/Users/Me/anaconda/envs/PythonData/lib/python3.6/site-packages/requests_toolbelt/threaded/thread.py\", line 45, in _make_request\n",
      "    self._handle_request(kwargs)\n",
      "  File \"/Users/Me/anaconda/envs/PythonData/lib/python3.6/site-packages/requests_toolbelt/threaded/thread.py\", line 32, in _handle_request\n",
      "    self._exceptions.put((kwargs, e))\n",
      "AttributeError: 'SessionThread' object has no attribute '_exceptions'\n",
      "\n",
      "Exception in thread cd643e2a-06b2-4be4-82e4-e366d60c2029:\n",
      "Traceback (most recent call last):\n",
      "  File \"/Users/Me/anaconda/envs/PythonData/lib/python3.6/site-packages/requests_toolbelt/threaded/thread.py\", line 30, in _handle_request\n",
      "    response = self._session.request(**kwargs)\n",
      "  File \"/Users/Me/anaconda/envs/PythonData/lib/python3.6/site-packages/requests/sessions.py\", line 504, in request\n",
      "    prep = self.prepare_request(req)\n",
      "  File \"/Users/Me/anaconda/envs/PythonData/lib/python3.6/site-packages/requests/sessions.py\", line 436, in prepare_request\n",
      "    hooks=merge_hooks(request.hooks, self.hooks),\n",
      "  File \"/Users/Me/anaconda/envs/PythonData/lib/python3.6/site-packages/requests/models.py\", line 302, in prepare\n",
      "    self.prepare_url(url, params)\n",
      "  File \"/Users/Me/anaconda/envs/PythonData/lib/python3.6/site-packages/requests/models.py\", line 382, in prepare_url\n",
      "    raise MissingSchema(error)\n",
      "requests.exceptions.MissingSchema: Invalid URL 'statuses': No schema supplied. Perhaps you meant http://statuses?\n",
      "\n",
      "During handling of the above exception, another exception occurred:\n",
      "\n",
      "Traceback (most recent call last):\n",
      "  File \"/Users/Me/anaconda/envs/PythonData/lib/python3.6/threading.py\", line 916, in _bootstrap_inner\n",
      "    self.run()\n",
      "  File \"/Users/Me/anaconda/envs/PythonData/lib/python3.6/threading.py\", line 864, in run\n",
      "    self._target(*self._args, **self._kwargs)\n",
      "  File \"/Users/Me/anaconda/envs/PythonData/lib/python3.6/site-packages/requests_toolbelt/threaded/thread.py\", line 45, in _make_request\n",
      "    self._handle_request(kwargs)\n",
      "  File \"/Users/Me/anaconda/envs/PythonData/lib/python3.6/site-packages/requests_toolbelt/threaded/thread.py\", line 32, in _handle_request\n",
      "    self._exceptions.put((kwargs, e))\n",
      "AttributeError: 'SessionThread' object has no attribute '_exceptions'\n",
      "\n",
      "Exception in thread 073b131d-3b06-4250-81ae-1af00a977283:\n",
      "Traceback (most recent call last):\n",
      "  File \"/Users/Me/anaconda/envs/PythonData/lib/python3.6/site-packages/requests_toolbelt/threaded/thread.py\", line 30, in _handle_request\n",
      "    response = self._session.request(**kwargs)\n",
      "  File \"/Users/Me/anaconda/envs/PythonData/lib/python3.6/site-packages/requests/sessions.py\", line 504, in request\n",
      "    prep = self.prepare_request(req)\n",
      "  File \"/Users/Me/anaconda/envs/PythonData/lib/python3.6/site-packages/requests/sessions.py\", line 436, in prepare_request\n",
      "    hooks=merge_hooks(request.hooks, self.hooks),\n",
      "  File \"/Users/Me/anaconda/envs/PythonData/lib/python3.6/site-packages/requests/models.py\", line 302, in prepare\n",
      "    self.prepare_url(url, params)\n",
      "  File \"/Users/Me/anaconda/envs/PythonData/lib/python3.6/site-packages/requests/models.py\", line 382, in prepare_url\n",
      "    raise MissingSchema(error)\n",
      "requests.exceptions.MissingSchema: Invalid URL 'search_metadata': No schema supplied. Perhaps you meant http://search_metadata?\n",
      "\n",
      "During handling of the above exception, another exception occurred:\n",
      "\n",
      "Traceback (most recent call last):\n",
      "  File \"/Users/Me/anaconda/envs/PythonData/lib/python3.6/threading.py\", line 916, in _bootstrap_inner\n",
      "    self.run()\n",
      "  File \"/Users/Me/anaconda/envs/PythonData/lib/python3.6/threading.py\", line 864, in run\n",
      "    self._target(*self._args, **self._kwargs)\n",
      "  File \"/Users/Me/anaconda/envs/PythonData/lib/python3.6/site-packages/requests_toolbelt/threaded/thread.py\", line 45, in _make_request\n",
      "    self._handle_request(kwargs)\n",
      "  File \"/Users/Me/anaconda/envs/PythonData/lib/python3.6/site-packages/requests_toolbelt/threaded/thread.py\", line 32, in _handle_request\n",
      "    self._exceptions.put((kwargs, e))\n",
      "AttributeError: 'SessionThread' object has no attribute '_exceptions'\n",
      "\n",
      "Exception in thread c8345e14-91ef-47ff-8c72-d7ed1e7dd828:\n",
      "Traceback (most recent call last):\n",
      "  File \"/Users/Me/anaconda/envs/PythonData/lib/python3.6/site-packages/requests_toolbelt/threaded/thread.py\", line 30, in _handle_request\n",
      "    response = self._session.request(**kwargs)\n",
      "  File \"/Users/Me/anaconda/envs/PythonData/lib/python3.6/site-packages/requests/sessions.py\", line 504, in request\n",
      "    prep = self.prepare_request(req)\n",
      "  File \"/Users/Me/anaconda/envs/PythonData/lib/python3.6/site-packages/requests/sessions.py\", line 436, in prepare_request\n",
      "    hooks=merge_hooks(request.hooks, self.hooks),\n",
      "  File \"/Users/Me/anaconda/envs/PythonData/lib/python3.6/site-packages/requests/models.py\", line 302, in prepare\n",
      "    self.prepare_url(url, params)\n",
      "  File \"/Users/Me/anaconda/envs/PythonData/lib/python3.6/site-packages/requests/models.py\", line 382, in prepare_url\n",
      "    raise MissingSchema(error)\n",
      "requests.exceptions.MissingSchema: Invalid URL 'statuses': No schema supplied. Perhaps you meant http://statuses?\n",
      "\n",
      "During handling of the above exception, another exception occurred:\n",
      "\n",
      "Traceback (most recent call last):\n",
      "  File \"/Users/Me/anaconda/envs/PythonData/lib/python3.6/threading.py\", line 916, in _bootstrap_inner\n",
      "    self.run()\n",
      "  File \"/Users/Me/anaconda/envs/PythonData/lib/python3.6/threading.py\", line 864, in run\n",
      "    self._target(*self._args, **self._kwargs)\n",
      "  File \"/Users/Me/anaconda/envs/PythonData/lib/python3.6/site-packages/requests_toolbelt/threaded/thread.py\", line 45, in _make_request\n",
      "    self._handle_request(kwargs)\n",
      "  File \"/Users/Me/anaconda/envs/PythonData/lib/python3.6/site-packages/requests_toolbelt/threaded/thread.py\", line 32, in _handle_request\n",
      "    self._exceptions.put((kwargs, e))\n",
      "AttributeError: 'SessionThread' object has no attribute '_exceptions'\n",
      "\n",
      "Exception in thread 72caca18-dad5-4ec1-aa54-8b3462fc4810:\n",
      "Traceback (most recent call last):\n",
      "  File \"/Users/Me/anaconda/envs/PythonData/lib/python3.6/site-packages/requests_toolbelt/threaded/thread.py\", line 30, in _handle_request\n",
      "    response = self._session.request(**kwargs)\n",
      "  File \"/Users/Me/anaconda/envs/PythonData/lib/python3.6/site-packages/requests/sessions.py\", line 504, in request\n",
      "    prep = self.prepare_request(req)\n",
      "  File \"/Users/Me/anaconda/envs/PythonData/lib/python3.6/site-packages/requests/sessions.py\", line 436, in prepare_request\n",
      "    hooks=merge_hooks(request.hooks, self.hooks),\n",
      "  File \"/Users/Me/anaconda/envs/PythonData/lib/python3.6/site-packages/requests/models.py\", line 302, in prepare\n",
      "    self.prepare_url(url, params)\n",
      "  File \"/Users/Me/anaconda/envs/PythonData/lib/python3.6/site-packages/requests/models.py\", line 382, in prepare_url\n",
      "    raise MissingSchema(error)\n",
      "requests.exceptions.MissingSchema: Invalid URL 'search_metadata': No schema supplied. Perhaps you meant http://search_metadata?\n",
      "\n",
      "During handling of the above exception, another exception occurred:\n",
      "\n",
      "Traceback (most recent call last):\n",
      "  File \"/Users/Me/anaconda/envs/PythonData/lib/python3.6/threading.py\", line 916, in _bootstrap_inner\n",
      "    self.run()\n",
      "  File \"/Users/Me/anaconda/envs/PythonData/lib/python3.6/threading.py\", line 864, in run\n",
      "    self._target(*self._args, **self._kwargs)\n",
      "  File \"/Users/Me/anaconda/envs/PythonData/lib/python3.6/site-packages/requests_toolbelt/threaded/thread.py\", line 45, in _make_request\n",
      "    self._handle_request(kwargs)\n",
      "  File \"/Users/Me/anaconda/envs/PythonData/lib/python3.6/site-packages/requests_toolbelt/threaded/thread.py\", line 32, in _handle_request\n",
      "    self._exceptions.put((kwargs, e))\n",
      "AttributeError: 'SessionThread' object has no attribute '_exceptions'\n",
      "\n"
     ]
    },
    {
     "name": "stderr",
     "output_type": "stream",
     "text": [
      "Exception in thread f9762a0b-37c7-4fa6-be17-d756c627258d:\n",
      "Traceback (most recent call last):\n",
      "  File \"/Users/Me/anaconda/envs/PythonData/lib/python3.6/site-packages/requests_toolbelt/threaded/thread.py\", line 30, in _handle_request\n",
      "    response = self._session.request(**kwargs)\n",
      "  File \"/Users/Me/anaconda/envs/PythonData/lib/python3.6/site-packages/requests/sessions.py\", line 504, in request\n",
      "    prep = self.prepare_request(req)\n",
      "  File \"/Users/Me/anaconda/envs/PythonData/lib/python3.6/site-packages/requests/sessions.py\", line 436, in prepare_request\n",
      "    hooks=merge_hooks(request.hooks, self.hooks),\n",
      "  File \"/Users/Me/anaconda/envs/PythonData/lib/python3.6/site-packages/requests/models.py\", line 302, in prepare\n",
      "    self.prepare_url(url, params)\n",
      "  File \"/Users/Me/anaconda/envs/PythonData/lib/python3.6/site-packages/requests/models.py\", line 382, in prepare_url\n",
      "    raise MissingSchema(error)\n",
      "requests.exceptions.MissingSchema: Invalid URL 'statuses': No schema supplied. Perhaps you meant http://statuses?\n",
      "\n",
      "During handling of the above exception, another exception occurred:\n",
      "\n",
      "Traceback (most recent call last):\n",
      "  File \"/Users/Me/anaconda/envs/PythonData/lib/python3.6/threading.py\", line 916, in _bootstrap_inner\n",
      "    self.run()\n",
      "  File \"/Users/Me/anaconda/envs/PythonData/lib/python3.6/threading.py\", line 864, in run\n",
      "    self._target(*self._args, **self._kwargs)\n",
      "  File \"/Users/Me/anaconda/envs/PythonData/lib/python3.6/site-packages/requests_toolbelt/threaded/thread.py\", line 45, in _make_request\n",
      "    self._handle_request(kwargs)\n",
      "  File \"/Users/Me/anaconda/envs/PythonData/lib/python3.6/site-packages/requests_toolbelt/threaded/thread.py\", line 32, in _handle_request\n",
      "    self._exceptions.put((kwargs, e))\n",
      "AttributeError: 'SessionThread' object has no attribute '_exceptions'\n",
      "\n",
      "Exception in thread e5d54e51-437a-49c7-8728-6601785c7325:\n",
      "Traceback (most recent call last):\n",
      "  File \"/Users/Me/anaconda/envs/PythonData/lib/python3.6/site-packages/requests_toolbelt/threaded/thread.py\", line 30, in _handle_request\n",
      "    response = self._session.request(**kwargs)\n",
      "  File \"/Users/Me/anaconda/envs/PythonData/lib/python3.6/site-packages/requests/sessions.py\", line 504, in request\n",
      "    prep = self.prepare_request(req)\n",
      "  File \"/Users/Me/anaconda/envs/PythonData/lib/python3.6/site-packages/requests/sessions.py\", line 436, in prepare_request\n",
      "    hooks=merge_hooks(request.hooks, self.hooks),\n",
      "  File \"/Users/Me/anaconda/envs/PythonData/lib/python3.6/site-packages/requests/models.py\", line 302, in prepare\n",
      "    self.prepare_url(url, params)\n",
      "  File \"/Users/Me/anaconda/envs/PythonData/lib/python3.6/site-packages/requests/models.py\", line 382, in prepare_url\n",
      "    raise MissingSchema(error)\n",
      "requests.exceptions.MissingSchema: Invalid URL 'search_metadata': No schema supplied. Perhaps you meant http://search_metadata?\n",
      "\n",
      "During handling of the above exception, another exception occurred:\n",
      "\n",
      "Traceback (most recent call last):\n",
      "  File \"/Users/Me/anaconda/envs/PythonData/lib/python3.6/threading.py\", line 916, in _bootstrap_inner\n",
      "    self.run()\n",
      "  File \"/Users/Me/anaconda/envs/PythonData/lib/python3.6/threading.py\", line 864, in run\n",
      "    self._target(*self._args, **self._kwargs)\n",
      "  File \"/Users/Me/anaconda/envs/PythonData/lib/python3.6/site-packages/requests_toolbelt/threaded/thread.py\", line 45, in _make_request\n",
      "    self._handle_request(kwargs)\n",
      "  File \"/Users/Me/anaconda/envs/PythonData/lib/python3.6/site-packages/requests_toolbelt/threaded/thread.py\", line 32, in _handle_request\n",
      "    self._exceptions.put((kwargs, e))\n",
      "AttributeError: 'SessionThread' object has no attribute '_exceptions'\n",
      "\n",
      "Exception in thread c01b6f80-57d6-4dac-a0ef-505ded851987:\n",
      "Traceback (most recent call last):\n",
      "  File \"/Users/Me/anaconda/envs/PythonData/lib/python3.6/site-packages/requests_toolbelt/threaded/thread.py\", line 30, in _handle_request\n",
      "    response = self._session.request(**kwargs)\n",
      "  File \"/Users/Me/anaconda/envs/PythonData/lib/python3.6/site-packages/requests/sessions.py\", line 504, in request\n",
      "    prep = self.prepare_request(req)\n",
      "  File \"/Users/Me/anaconda/envs/PythonData/lib/python3.6/site-packages/requests/sessions.py\", line 436, in prepare_request\n",
      "    hooks=merge_hooks(request.hooks, self.hooks),\n",
      "  File \"/Users/Me/anaconda/envs/PythonData/lib/python3.6/site-packages/requests/models.py\", line 302, in prepare\n",
      "    self.prepare_url(url, params)\n",
      "  File \"/Users/Me/anaconda/envs/PythonData/lib/python3.6/site-packages/requests/models.py\", line 382, in prepare_url\n",
      "    raise MissingSchema(error)\n",
      "requests.exceptions.MissingSchema: Invalid URL 'statuses': No schema supplied. Perhaps you meant http://statuses?\n",
      "\n",
      "During handling of the above exception, another exception occurred:\n",
      "\n",
      "Traceback (most recent call last):\n",
      "  File \"/Users/Me/anaconda/envs/PythonData/lib/python3.6/threading.py\", line 916, in _bootstrap_inner\n",
      "    self.run()\n",
      "  File \"/Users/Me/anaconda/envs/PythonData/lib/python3.6/threading.py\", line 864, in run\n",
      "    self._target(*self._args, **self._kwargs)\n",
      "  File \"/Users/Me/anaconda/envs/PythonData/lib/python3.6/site-packages/requests_toolbelt/threaded/thread.py\", line 45, in _make_request\n",
      "    self._handle_request(kwargs)\n",
      "  File \"/Users/Me/anaconda/envs/PythonData/lib/python3.6/site-packages/requests_toolbelt/threaded/thread.py\", line 32, in _handle_request\n",
      "    self._exceptions.put((kwargs, e))\n",
      "AttributeError: 'SessionThread' object has no attribute '_exceptions'\n",
      "Exception in thread e78e3a61-f70e-4443-98c7-3b7c8468d59c:\n",
      "Traceback (most recent call last):\n",
      "  File \"/Users/Me/anaconda/envs/PythonData/lib/python3.6/site-packages/requests_toolbelt/threaded/thread.py\", line 30, in _handle_request\n",
      "    response = self._session.request(**kwargs)\n",
      "  File \"/Users/Me/anaconda/envs/PythonData/lib/python3.6/site-packages/requests/sessions.py\", line 504, in request\n",
      "    prep = self.prepare_request(req)\n",
      "  File \"/Users/Me/anaconda/envs/PythonData/lib/python3.6/site-packages/requests/sessions.py\", line 436, in prepare_request\n",
      "    hooks=merge_hooks(request.hooks, self.hooks),\n",
      "  File \"/Users/Me/anaconda/envs/PythonData/lib/python3.6/site-packages/requests/models.py\", line 302, in prepare\n",
      "    self.prepare_url(url, params)\n",
      "  File \"/Users/Me/anaconda/envs/PythonData/lib/python3.6/site-packages/requests/models.py\", line 382, in prepare_url\n",
      "    raise MissingSchema(error)\n",
      "requests.exceptions.MissingSchema: Invalid URL 'search_metadata': No schema supplied. Perhaps you meant http://search_metadata?\n",
      "\n",
      "During handling of the above exception, another exception occurred:\n",
      "\n",
      "Traceback (most recent call last):\n",
      "  File \"/Users/Me/anaconda/envs/PythonData/lib/python3.6/threading.py\", line 916, in _bootstrap_inner\n",
      "    self.run()\n",
      "  File \"/Users/Me/anaconda/envs/PythonData/lib/python3.6/threading.py\", line 864, in run\n",
      "    self._target(*self._args, **self._kwargs)\n",
      "  File \"/Users/Me/anaconda/envs/PythonData/lib/python3.6/site-packages/requests_toolbelt/threaded/thread.py\", line 45, in _make_request\n",
      "    self._handle_request(kwargs)\n",
      "  File \"/Users/Me/anaconda/envs/PythonData/lib/python3.6/site-packages/requests_toolbelt/threaded/thread.py\", line 32, in _handle_request\n",
      "    self._exceptions.put((kwargs, e))\n",
      "AttributeError: 'SessionThread' object has no attribute '_exceptions'\n",
      "\n",
      "\n",
      "Exception in thread d626fe7d-00f4-499c-96df-9ec9899eac3f:\n",
      "Traceback (most recent call last):\n",
      "  File \"/Users/Me/anaconda/envs/PythonData/lib/python3.6/site-packages/requests_toolbelt/threaded/thread.py\", line 30, in _handle_request\n",
      "    response = self._session.request(**kwargs)\n",
      "  File \"/Users/Me/anaconda/envs/PythonData/lib/python3.6/site-packages/requests/sessions.py\", line 504, in request\n",
      "    prep = self.prepare_request(req)\n",
      "  File \"/Users/Me/anaconda/envs/PythonData/lib/python3.6/site-packages/requests/sessions.py\", line 436, in prepare_request\n",
      "    hooks=merge_hooks(request.hooks, self.hooks),\n",
      "  File \"/Users/Me/anaconda/envs/PythonData/lib/python3.6/site-packages/requests/models.py\", line 302, in prepare\n",
      "    self.prepare_url(url, params)\n",
      "  File \"/Users/Me/anaconda/envs/PythonData/lib/python3.6/site-packages/requests/models.py\", line 382, in prepare_url\n",
      "    raise MissingSchema(error)\n",
      "requests.exceptions.MissingSchema: Invalid URL 'statuses': No schema supplied. Perhaps you meant http://statuses?\n",
      "\n",
      "During handling of the above exception, another exception occurred:\n",
      "\n",
      "Traceback (most recent call last):\n",
      "  File \"/Users/Me/anaconda/envs/PythonData/lib/python3.6/threading.py\", line 916, in _bootstrap_inner\n",
      "    self.run()\n",
      "  File \"/Users/Me/anaconda/envs/PythonData/lib/python3.6/threading.py\", line 864, in run\n",
      "    self._target(*self._args, **self._kwargs)\n",
      "  File \"/Users/Me/anaconda/envs/PythonData/lib/python3.6/site-packages/requests_toolbelt/threaded/thread.py\", line 45, in _make_request\n",
      "    self._handle_request(kwargs)\n",
      "  File \"/Users/Me/anaconda/envs/PythonData/lib/python3.6/site-packages/requests_toolbelt/threaded/thread.py\", line 32, in _handle_request\n",
      "    self._exceptions.put((kwargs, e))\n",
      "AttributeError: 'SessionThread' object has no attribute '_exceptions'\n",
      "\n",
      "Exception in thread 03fcd804-9b1d-41e6-ac8e-74660cebc006:\n",
      "Traceback (most recent call last):\n",
      "  File \"/Users/Me/anaconda/envs/PythonData/lib/python3.6/site-packages/requests_toolbelt/threaded/thread.py\", line 30, in _handle_request\n",
      "    response = self._session.request(**kwargs)\n",
      "  File \"/Users/Me/anaconda/envs/PythonData/lib/python3.6/site-packages/requests/sessions.py\", line 504, in request\n",
      "    prep = self.prepare_request(req)\n",
      "  File \"/Users/Me/anaconda/envs/PythonData/lib/python3.6/site-packages/requests/sessions.py\", line 436, in prepare_request\n",
      "    hooks=merge_hooks(request.hooks, self.hooks),\n",
      "  File \"/Users/Me/anaconda/envs/PythonData/lib/python3.6/site-packages/requests/models.py\", line 302, in prepare\n",
      "    self.prepare_url(url, params)\n",
      "  File \"/Users/Me/anaconda/envs/PythonData/lib/python3.6/site-packages/requests/models.py\", line 382, in prepare_url\n",
      "    raise MissingSchema(error)\n",
      "requests.exceptions.MissingSchema: Invalid URL 'search_metadata': No schema supplied. Perhaps you meant http://search_metadata?\n",
      "\n",
      "During handling of the above exception, another exception occurred:\n",
      "\n",
      "Traceback (most recent call last):\n",
      "  File \"/Users/Me/anaconda/envs/PythonData/lib/python3.6/threading.py\", line 916, in _bootstrap_inner\n",
      "    self.run()\n",
      "  File \"/Users/Me/anaconda/envs/PythonData/lib/python3.6/threading.py\", line 864, in run\n",
      "    self._target(*self._args, **self._kwargs)\n",
      "  File \"/Users/Me/anaconda/envs/PythonData/lib/python3.6/site-packages/requests_toolbelt/threaded/thread.py\", line 45, in _make_request\n",
      "    self._handle_request(kwargs)\n",
      "  File \"/Users/Me/anaconda/envs/PythonData/lib/python3.6/site-packages/requests_toolbelt/threaded/thread.py\", line 32, in _handle_request\n",
      "    self._exceptions.put((kwargs, e))\n",
      "AttributeError: 'SessionThread' object has no attribute '_exceptions'\n",
      "\n"
     ]
    },
    {
     "name": "stderr",
     "output_type": "stream",
     "text": [
      "Exception in thread 551abed8-949d-494f-85ad-b8ccc3012ba4:\n",
      "Traceback (most recent call last):\n",
      "  File \"/Users/Me/anaconda/envs/PythonData/lib/python3.6/site-packages/requests_toolbelt/threaded/thread.py\", line 30, in _handle_request\n",
      "    response = self._session.request(**kwargs)\n",
      "  File \"/Users/Me/anaconda/envs/PythonData/lib/python3.6/site-packages/requests/sessions.py\", line 504, in request\n",
      "    prep = self.prepare_request(req)\n",
      "  File \"/Users/Me/anaconda/envs/PythonData/lib/python3.6/site-packages/requests/sessions.py\", line 436, in prepare_request\n",
      "    hooks=merge_hooks(request.hooks, self.hooks),\n",
      "  File \"/Users/Me/anaconda/envs/PythonData/lib/python3.6/site-packages/requests/models.py\", line 302, in prepare\n",
      "    self.prepare_url(url, params)\n",
      "  File \"/Users/Me/anaconda/envs/PythonData/lib/python3.6/site-packages/requests/models.py\", line 382, in prepare_url\n",
      "    raise MissingSchema(error)\n",
      "requests.exceptions.MissingSchema: Invalid URL 'statuses': No schema supplied. Perhaps you meant http://statuses?\n",
      "\n",
      "During handling of the above exception, another exception occurred:\n",
      "\n",
      "Traceback (most recent call last):\n",
      "  File \"/Users/Me/anaconda/envs/PythonData/lib/python3.6/threading.py\", line 916, in _bootstrap_inner\n",
      "    self.run()\n",
      "  File \"/Users/Me/anaconda/envs/PythonData/lib/python3.6/threading.py\", line 864, in run\n",
      "    self._target(*self._args, **self._kwargs)\n",
      "  File \"/Users/Me/anaconda/envs/PythonData/lib/python3.6/site-packages/requests_toolbelt/threaded/thread.py\", line 45, in _make_request\n",
      "    self._handle_request(kwargs)\n",
      "  File \"/Users/Me/anaconda/envs/PythonData/lib/python3.6/site-packages/requests_toolbelt/threaded/thread.py\", line 32, in _handle_request\n",
      "    self._exceptions.put((kwargs, e))\n",
      "AttributeError: 'SessionThread' object has no attribute '_exceptions'\n",
      "\n",
      "Exception in thread b169a140-f58c-4eca-8b97-c9031d6c2440:\n",
      "Traceback (most recent call last):\n",
      "  File \"/Users/Me/anaconda/envs/PythonData/lib/python3.6/site-packages/requests_toolbelt/threaded/thread.py\", line 30, in _handle_request\n",
      "    response = self._session.request(**kwargs)\n",
      "  File \"/Users/Me/anaconda/envs/PythonData/lib/python3.6/site-packages/requests/sessions.py\", line 504, in request\n",
      "    prep = self.prepare_request(req)\n",
      "  File \"/Users/Me/anaconda/envs/PythonData/lib/python3.6/site-packages/requests/sessions.py\", line 436, in prepare_request\n",
      "    hooks=merge_hooks(request.hooks, self.hooks),\n",
      "  File \"/Users/Me/anaconda/envs/PythonData/lib/python3.6/site-packages/requests/models.py\", line 302, in prepare\n",
      "    self.prepare_url(url, params)\n",
      "  File \"/Users/Me/anaconda/envs/PythonData/lib/python3.6/site-packages/requests/models.py\", line 382, in prepare_url\n",
      "    raise MissingSchema(error)\n",
      "requests.exceptions.MissingSchema: Invalid URL 'search_metadata': No schema supplied. Perhaps you meant http://search_metadata?\n",
      "\n",
      "During handling of the above exception, another exception occurred:\n",
      "\n",
      "Traceback (most recent call last):\n",
      "  File \"/Users/Me/anaconda/envs/PythonData/lib/python3.6/threading.py\", line 916, in _bootstrap_inner\n",
      "    self.run()\n",
      "  File \"/Users/Me/anaconda/envs/PythonData/lib/python3.6/threading.py\", line 864, in run\n",
      "    self._target(*self._args, **self._kwargs)\n",
      "  File \"/Users/Me/anaconda/envs/PythonData/lib/python3.6/site-packages/requests_toolbelt/threaded/thread.py\", line 45, in _make_request\n",
      "    self._handle_request(kwargs)\n",
      "  File \"/Users/Me/anaconda/envs/PythonData/lib/python3.6/site-packages/requests_toolbelt/threaded/thread.py\", line 32, in _handle_request\n",
      "    self._exceptions.put((kwargs, e))\n",
      "AttributeError: 'SessionThread' object has no attribute '_exceptions'\n",
      "\n",
      "Exception in thread df7d4bfb-785a-40e4-8a5e-5a09715e4413:\n",
      "Traceback (most recent call last):\n",
      "  File \"/Users/Me/anaconda/envs/PythonData/lib/python3.6/site-packages/requests_toolbelt/threaded/thread.py\", line 30, in _handle_request\n",
      "    response = self._session.request(**kwargs)\n",
      "  File \"/Users/Me/anaconda/envs/PythonData/lib/python3.6/site-packages/requests/sessions.py\", line 504, in request\n",
      "    prep = self.prepare_request(req)\n",
      "  File \"/Users/Me/anaconda/envs/PythonData/lib/python3.6/site-packages/requests/sessions.py\", line 436, in prepare_request\n",
      "    hooks=merge_hooks(request.hooks, self.hooks),\n",
      "  File \"/Users/Me/anaconda/envs/PythonData/lib/python3.6/site-packages/requests/models.py\", line 302, in prepare\n",
      "    self.prepare_url(url, params)\n",
      "  File \"/Users/Me/anaconda/envs/PythonData/lib/python3.6/site-packages/requests/models.py\", line 382, in prepare_url\n",
      "    raise MissingSchema(error)\n",
      "requests.exceptions.MissingSchema: Invalid URL 'statuses': No schema supplied. Perhaps you meant http://statuses?\n",
      "\n",
      "During handling of the above exception, another exception occurred:\n",
      "\n",
      "Traceback (most recent call last):\n",
      "  File \"/Users/Me/anaconda/envs/PythonData/lib/python3.6/threading.py\", line 916, in _bootstrap_inner\n",
      "    self.run()\n",
      "  File \"/Users/Me/anaconda/envs/PythonData/lib/python3.6/threading.py\", line 864, in run\n",
      "    self._target(*self._args, **self._kwargs)\n",
      "  File \"/Users/Me/anaconda/envs/PythonData/lib/python3.6/site-packages/requests_toolbelt/threaded/thread.py\", line 45, in _make_request\n",
      "    self._handle_request(kwargs)\n",
      "  File \"/Users/Me/anaconda/envs/PythonData/lib/python3.6/site-packages/requests_toolbelt/threaded/thread.py\", line 32, in _handle_request\n",
      "    self._exceptions.put((kwargs, e))\n",
      "AttributeError: 'SessionThread' object has no attribute '_exceptions'\n",
      "\n",
      "Exception in thread 00c4e355-8d95-498f-8514-eb61ee9243a4:\n",
      "Traceback (most recent call last):\n",
      "  File \"/Users/Me/anaconda/envs/PythonData/lib/python3.6/site-packages/requests_toolbelt/threaded/thread.py\", line 30, in _handle_request\n",
      "    response = self._session.request(**kwargs)\n",
      "  File \"/Users/Me/anaconda/envs/PythonData/lib/python3.6/site-packages/requests/sessions.py\", line 504, in request\n",
      "    prep = self.prepare_request(req)\n",
      "  File \"/Users/Me/anaconda/envs/PythonData/lib/python3.6/site-packages/requests/sessions.py\", line 436, in prepare_request\n",
      "    hooks=merge_hooks(request.hooks, self.hooks),\n",
      "  File \"/Users/Me/anaconda/envs/PythonData/lib/python3.6/site-packages/requests/models.py\", line 302, in prepare\n",
      "    self.prepare_url(url, params)\n",
      "  File \"/Users/Me/anaconda/envs/PythonData/lib/python3.6/site-packages/requests/models.py\", line 382, in prepare_url\n",
      "    raise MissingSchema(error)\n",
      "requests.exceptions.MissingSchema: Invalid URL 'search_metadata': No schema supplied. Perhaps you meant http://search_metadata?\n",
      "\n",
      "During handling of the above exception, another exception occurred:\n",
      "\n",
      "Traceback (most recent call last):\n",
      "  File \"/Users/Me/anaconda/envs/PythonData/lib/python3.6/threading.py\", line 916, in _bootstrap_inner\n",
      "    self.run()\n",
      "  File \"/Users/Me/anaconda/envs/PythonData/lib/python3.6/threading.py\", line 864, in run\n",
      "    self._target(*self._args, **self._kwargs)\n",
      "  File \"/Users/Me/anaconda/envs/PythonData/lib/python3.6/site-packages/requests_toolbelt/threaded/thread.py\", line 45, in _make_request\n",
      "    self._handle_request(kwargs)\n",
      "  File \"/Users/Me/anaconda/envs/PythonData/lib/python3.6/site-packages/requests_toolbelt/threaded/thread.py\", line 32, in _handle_request\n",
      "    self._exceptions.put((kwargs, e))\n",
      "AttributeError: 'SessionThread' object has no attribute '_exceptions'\n",
      "\n",
      "Exception in thread f1175445-d92f-4b3e-ab60-c955464e80cc:\n",
      "Traceback (most recent call last):\n",
      "  File \"/Users/Me/anaconda/envs/PythonData/lib/python3.6/site-packages/requests_toolbelt/threaded/thread.py\", line 30, in _handle_request\n",
      "    response = self._session.request(**kwargs)\n",
      "  File \"/Users/Me/anaconda/envs/PythonData/lib/python3.6/site-packages/requests/sessions.py\", line 504, in request\n",
      "    prep = self.prepare_request(req)\n",
      "  File \"/Users/Me/anaconda/envs/PythonData/lib/python3.6/site-packages/requests/sessions.py\", line 436, in prepare_request\n",
      "    hooks=merge_hooks(request.hooks, self.hooks),\n",
      "  File \"/Users/Me/anaconda/envs/PythonData/lib/python3.6/site-packages/requests/models.py\", line 302, in prepare\n",
      "    self.prepare_url(url, params)\n",
      "  File \"/Users/Me/anaconda/envs/PythonData/lib/python3.6/site-packages/requests/models.py\", line 382, in prepare_url\n",
      "    raise MissingSchema(error)\n",
      "requests.exceptions.MissingSchema: Invalid URL 'statuses': No schema supplied. Perhaps you meant http://statuses?\n",
      "\n",
      "During handling of the above exception, another exception occurred:\n",
      "\n",
      "Traceback (most recent call last):\n",
      "  File \"/Users/Me/anaconda/envs/PythonData/lib/python3.6/threading.py\", line 916, in _bootstrap_inner\n",
      "    self.run()\n",
      "  File \"/Users/Me/anaconda/envs/PythonData/lib/python3.6/threading.py\", line 864, in run\n",
      "    self._target(*self._args, **self._kwargs)\n",
      "  File \"/Users/Me/anaconda/envs/PythonData/lib/python3.6/site-packages/requests_toolbelt/threaded/thread.py\", line 45, in _make_request\n",
      "    self._handle_request(kwargs)\n",
      "  File \"/Users/Me/anaconda/envs/PythonData/lib/python3.6/site-packages/requests_toolbelt/threaded/thread.py\", line 32, in _handle_request\n",
      "    self._exceptions.put((kwargs, e))\n",
      "AttributeError: 'SessionThread' object has no attribute '_exceptions'\n",
      "Exception in thread 9b711e1b-2acf-4efd-bda9-e89d3870e917:\n",
      "Traceback (most recent call last):\n",
      "  File \"/Users/Me/anaconda/envs/PythonData/lib/python3.6/site-packages/requests_toolbelt/threaded/thread.py\", line 30, in _handle_request\n",
      "    response = self._session.request(**kwargs)\n",
      "  File \"/Users/Me/anaconda/envs/PythonData/lib/python3.6/site-packages/requests/sessions.py\", line 504, in request\n",
      "    prep = self.prepare_request(req)\n",
      "  File \"/Users/Me/anaconda/envs/PythonData/lib/python3.6/site-packages/requests/sessions.py\", line 436, in prepare_request\n",
      "    hooks=merge_hooks(request.hooks, self.hooks),\n",
      "  File \"/Users/Me/anaconda/envs/PythonData/lib/python3.6/site-packages/requests/models.py\", line 302, in prepare\n",
      "    self.prepare_url(url, params)\n",
      "  File \"/Users/Me/anaconda/envs/PythonData/lib/python3.6/site-packages/requests/models.py\", line 382, in prepare_url\n",
      "    raise MissingSchema(error)\n",
      "requests.exceptions.MissingSchema: Invalid URL 'search_metadata': No schema supplied. Perhaps you meant http://search_metadata?\n",
      "\n",
      "During handling of the above exception, another exception occurred:\n",
      "\n",
      "Traceback (most recent call last):\n",
      "  File \"/Users/Me/anaconda/envs/PythonData/lib/python3.6/threading.py\", line 916, in _bootstrap_inner\n",
      "    self.run()\n",
      "  File \"/Users/Me/anaconda/envs/PythonData/lib/python3.6/threading.py\", line 864, in run\n",
      "    self._target(*self._args, **self._kwargs)\n",
      "  File \"/Users/Me/anaconda/envs/PythonData/lib/python3.6/site-packages/requests_toolbelt/threaded/thread.py\", line 45, in _make_request\n",
      "    self._handle_request(kwargs)\n",
      "  File \"/Users/Me/anaconda/envs/PythonData/lib/python3.6/site-packages/requests_toolbelt/threaded/thread.py\", line 32, in _handle_request\n",
      "    self._exceptions.put((kwargs, e))\n",
      "AttributeError: 'SessionThread' object has no attribute '_exceptions'\n",
      "\n",
      "\n"
     ]
    },
    {
     "name": "stderr",
     "output_type": "stream",
     "text": [
      "Exception in thread 0a6cecfd-2978-411d-9204-697ced0248cf:\n",
      "Traceback (most recent call last):\n",
      "  File \"/Users/Me/anaconda/envs/PythonData/lib/python3.6/site-packages/requests_toolbelt/threaded/thread.py\", line 30, in _handle_request\n",
      "    response = self._session.request(**kwargs)\n",
      "  File \"/Users/Me/anaconda/envs/PythonData/lib/python3.6/site-packages/requests/sessions.py\", line 504, in request\n",
      "    prep = self.prepare_request(req)\n",
      "  File \"/Users/Me/anaconda/envs/PythonData/lib/python3.6/site-packages/requests/sessions.py\", line 436, in prepare_request\n",
      "    hooks=merge_hooks(request.hooks, self.hooks),\n",
      "  File \"/Users/Me/anaconda/envs/PythonData/lib/python3.6/site-packages/requests/models.py\", line 302, in prepare\n",
      "    self.prepare_url(url, params)\n",
      "  File \"/Users/Me/anaconda/envs/PythonData/lib/python3.6/site-packages/requests/models.py\", line 382, in prepare_url\n",
      "    raise MissingSchema(error)\n",
      "requests.exceptions.MissingSchema: Invalid URL 'statuses': No schema supplied. Perhaps you meant http://statuses?\n",
      "\n",
      "During handling of the above exception, another exception occurred:\n",
      "\n",
      "Traceback (most recent call last):\n",
      "  File \"/Users/Me/anaconda/envs/PythonData/lib/python3.6/threading.py\", line 916, in _bootstrap_inner\n",
      "    self.run()\n",
      "  File \"/Users/Me/anaconda/envs/PythonData/lib/python3.6/threading.py\", line 864, in run\n",
      "    self._target(*self._args, **self._kwargs)\n",
      "  File \"/Users/Me/anaconda/envs/PythonData/lib/python3.6/site-packages/requests_toolbelt/threaded/thread.py\", line 45, in _make_request\n",
      "    self._handle_request(kwargs)\n",
      "  File \"/Users/Me/anaconda/envs/PythonData/lib/python3.6/site-packages/requests_toolbelt/threaded/thread.py\", line 32, in _handle_request\n",
      "    self._exceptions.put((kwargs, e))\n",
      "AttributeError: 'SessionThread' object has no attribute '_exceptions'\n",
      "Exception in thread f8c12cdf-98cb-47cb-b69b-2183dcc6c898:\n",
      "Traceback (most recent call last):\n",
      "  File \"/Users/Me/anaconda/envs/PythonData/lib/python3.6/site-packages/requests_toolbelt/threaded/thread.py\", line 30, in _handle_request\n",
      "    response = self._session.request(**kwargs)\n",
      "  File \"/Users/Me/anaconda/envs/PythonData/lib/python3.6/site-packages/requests/sessions.py\", line 504, in request\n",
      "    prep = self.prepare_request(req)\n",
      "  File \"/Users/Me/anaconda/envs/PythonData/lib/python3.6/site-packages/requests/sessions.py\", line 436, in prepare_request\n",
      "    hooks=merge_hooks(request.hooks, self.hooks),\n",
      "  File \"/Users/Me/anaconda/envs/PythonData/lib/python3.6/site-packages/requests/models.py\", line 302, in prepare\n",
      "    self.prepare_url(url, params)\n",
      "  File \"/Users/Me/anaconda/envs/PythonData/lib/python3.6/site-packages/requests/models.py\", line 382, in prepare_url\n",
      "    raise MissingSchema(error)\n",
      "requests.exceptions.MissingSchema: Invalid URL 'search_metadata': No schema supplied. Perhaps you meant http://search_metadata?\n",
      "\n",
      "During handling of the above exception, another exception occurred:\n",
      "\n",
      "Traceback (most recent call last):\n",
      "  File \"/Users/Me/anaconda/envs/PythonData/lib/python3.6/threading.py\", line 916, in _bootstrap_inner\n",
      "    self.run()\n",
      "  File \"/Users/Me/anaconda/envs/PythonData/lib/python3.6/threading.py\", line 864, in run\n",
      "    self._target(*self._args, **self._kwargs)\n",
      "  File \"/Users/Me/anaconda/envs/PythonData/lib/python3.6/site-packages/requests_toolbelt/threaded/thread.py\", line 45, in _make_request\n",
      "    self._handle_request(kwargs)\n",
      "  File \"/Users/Me/anaconda/envs/PythonData/lib/python3.6/site-packages/requests_toolbelt/threaded/thread.py\", line 32, in _handle_request\n",
      "    self._exceptions.put((kwargs, e))\n",
      "AttributeError: 'SessionThread' object has no attribute '_exceptions'\n",
      "\n",
      "\n",
      "Exception in thread f98e7d4b-977f-4520-8ebd-42c0f7a5bc44:\n",
      "Traceback (most recent call last):\n",
      "  File \"/Users/Me/anaconda/envs/PythonData/lib/python3.6/site-packages/requests_toolbelt/threaded/thread.py\", line 30, in _handle_request\n",
      "    response = self._session.request(**kwargs)\n",
      "  File \"/Users/Me/anaconda/envs/PythonData/lib/python3.6/site-packages/requests/sessions.py\", line 504, in request\n",
      "    prep = self.prepare_request(req)\n",
      "  File \"/Users/Me/anaconda/envs/PythonData/lib/python3.6/site-packages/requests/sessions.py\", line 436, in prepare_request\n",
      "    hooks=merge_hooks(request.hooks, self.hooks),\n",
      "  File \"/Users/Me/anaconda/envs/PythonData/lib/python3.6/site-packages/requests/models.py\", line 302, in prepare\n",
      "    self.prepare_url(url, params)\n",
      "  File \"/Users/Me/anaconda/envs/PythonData/lib/python3.6/site-packages/requests/models.py\", line 382, in prepare_url\n",
      "    raise MissingSchema(error)\n",
      "requests.exceptions.MissingSchema: Invalid URL 'statuses': No schema supplied. Perhaps you meant http://statuses?\n",
      "\n",
      "During handling of the above exception, another exception occurred:\n",
      "\n",
      "Traceback (most recent call last):\n",
      "  File \"/Users/Me/anaconda/envs/PythonData/lib/python3.6/threading.py\", line 916, in _bootstrap_inner\n",
      "    self.run()\n",
      "  File \"/Users/Me/anaconda/envs/PythonData/lib/python3.6/threading.py\", line 864, in run\n",
      "    self._target(*self._args, **self._kwargs)\n",
      "  File \"/Users/Me/anaconda/envs/PythonData/lib/python3.6/site-packages/requests_toolbelt/threaded/thread.py\", line 45, in _make_request\n",
      "    self._handle_request(kwargs)\n",
      "  File \"/Users/Me/anaconda/envs/PythonData/lib/python3.6/site-packages/requests_toolbelt/threaded/thread.py\", line 32, in _handle_request\n",
      "    self._exceptions.put((kwargs, e))\n",
      "AttributeError: 'SessionThread' object has no attribute '_exceptions'\n",
      "Exception in thread b06e9ab6-092b-4f5c-b9de-35c13bcbb1f4:\n",
      "Traceback (most recent call last):\n",
      "  File \"/Users/Me/anaconda/envs/PythonData/lib/python3.6/site-packages/requests_toolbelt/threaded/thread.py\", line 30, in _handle_request\n",
      "    response = self._session.request(**kwargs)\n",
      "  File \"/Users/Me/anaconda/envs/PythonData/lib/python3.6/site-packages/requests/sessions.py\", line 504, in request\n",
      "    prep = self.prepare_request(req)\n",
      "  File \"/Users/Me/anaconda/envs/PythonData/lib/python3.6/site-packages/requests/sessions.py\", line 436, in prepare_request\n",
      "    hooks=merge_hooks(request.hooks, self.hooks),\n",
      "  File \"/Users/Me/anaconda/envs/PythonData/lib/python3.6/site-packages/requests/models.py\", line 302, in prepare\n",
      "    self.prepare_url(url, params)\n",
      "  File \"/Users/Me/anaconda/envs/PythonData/lib/python3.6/site-packages/requests/models.py\", line 382, in prepare_url\n",
      "    raise MissingSchema(error)\n",
      "requests.exceptions.MissingSchema: Invalid URL 'search_metadata': No schema supplied. Perhaps you meant http://search_metadata?\n",
      "\n",
      "During handling of the above exception, another exception occurred:\n",
      "\n",
      "Traceback (most recent call last):\n",
      "  File \"/Users/Me/anaconda/envs/PythonData/lib/python3.6/threading.py\", line 916, in _bootstrap_inner\n",
      "    self.run()\n",
      "  File \"/Users/Me/anaconda/envs/PythonData/lib/python3.6/threading.py\", line 864, in run\n",
      "    self._target(*self._args, **self._kwargs)\n",
      "  File \"/Users/Me/anaconda/envs/PythonData/lib/python3.6/site-packages/requests_toolbelt/threaded/thread.py\", line 45, in _make_request\n",
      "    self._handle_request(kwargs)\n",
      "  File \"/Users/Me/anaconda/envs/PythonData/lib/python3.6/site-packages/requests_toolbelt/threaded/thread.py\", line 32, in _handle_request\n",
      "    self._exceptions.put((kwargs, e))\n",
      "AttributeError: 'SessionThread' object has no attribute '_exceptions'\n",
      "\n",
      "\n",
      "Exception in thread 46af1dab-6a38-4348-afdf-e33c9d28354f:\n",
      "Traceback (most recent call last):\n",
      "  File \"/Users/Me/anaconda/envs/PythonData/lib/python3.6/site-packages/requests_toolbelt/threaded/thread.py\", line 30, in _handle_request\n",
      "    response = self._session.request(**kwargs)\n",
      "  File \"/Users/Me/anaconda/envs/PythonData/lib/python3.6/site-packages/requests/sessions.py\", line 504, in request\n",
      "    prep = self.prepare_request(req)\n",
      "  File \"/Users/Me/anaconda/envs/PythonData/lib/python3.6/site-packages/requests/sessions.py\", line 436, in prepare_request\n",
      "    hooks=merge_hooks(request.hooks, self.hooks),\n",
      "  File \"/Users/Me/anaconda/envs/PythonData/lib/python3.6/site-packages/requests/models.py\", line 302, in prepare\n",
      "    self.prepare_url(url, params)\n",
      "  File \"/Users/Me/anaconda/envs/PythonData/lib/python3.6/site-packages/requests/models.py\", line 382, in prepare_url\n",
      "    raise MissingSchema(error)\n",
      "requests.exceptions.MissingSchema: Invalid URL 'statuses': No schema supplied. Perhaps you meant http://statuses?\n",
      "\n",
      "During handling of the above exception, another exception occurred:\n",
      "\n",
      "Traceback (most recent call last):\n",
      "  File \"/Users/Me/anaconda/envs/PythonData/lib/python3.6/threading.py\", line 916, in _bootstrap_inner\n",
      "    self.run()\n",
      "  File \"/Users/Me/anaconda/envs/PythonData/lib/python3.6/threading.py\", line 864, in run\n",
      "    self._target(*self._args, **self._kwargs)\n",
      "  File \"/Users/Me/anaconda/envs/PythonData/lib/python3.6/site-packages/requests_toolbelt/threaded/thread.py\", line 45, in _make_request\n",
      "    self._handle_request(kwargs)\n",
      "  File \"/Users/Me/anaconda/envs/PythonData/lib/python3.6/site-packages/requests_toolbelt/threaded/thread.py\", line 32, in _handle_request\n",
      "    self._exceptions.put((kwargs, e))\n",
      "AttributeError: 'SessionThread' object has no attribute '_exceptions'\n",
      "Exception in thread ae788ed4-2f71-4571-8507-6e18c9988631:\n",
      "Traceback (most recent call last):\n",
      "  File \"/Users/Me/anaconda/envs/PythonData/lib/python3.6/site-packages/requests_toolbelt/threaded/thread.py\", line 30, in _handle_request\n",
      "    response = self._session.request(**kwargs)\n",
      "  File \"/Users/Me/anaconda/envs/PythonData/lib/python3.6/site-packages/requests/sessions.py\", line 504, in request\n",
      "    prep = self.prepare_request(req)\n",
      "  File \"/Users/Me/anaconda/envs/PythonData/lib/python3.6/site-packages/requests/sessions.py\", line 436, in prepare_request\n",
      "    hooks=merge_hooks(request.hooks, self.hooks),\n",
      "  File \"/Users/Me/anaconda/envs/PythonData/lib/python3.6/site-packages/requests/models.py\", line 302, in prepare\n",
      "    self.prepare_url(url, params)\n",
      "  File \"/Users/Me/anaconda/envs/PythonData/lib/python3.6/site-packages/requests/models.py\", line 382, in prepare_url\n",
      "    raise MissingSchema(error)\n",
      "requests.exceptions.MissingSchema: Invalid URL 'search_metadata': No schema supplied. Perhaps you meant http://search_metadata?\n",
      "\n",
      "During handling of the above exception, another exception occurred:\n",
      "\n",
      "Traceback (most recent call last):\n",
      "  File \"/Users/Me/anaconda/envs/PythonData/lib/python3.6/threading.py\", line 916, in _bootstrap_inner\n",
      "    self.run()\n",
      "  File \"/Users/Me/anaconda/envs/PythonData/lib/python3.6/threading.py\", line 864, in run\n",
      "    self._target(*self._args, **self._kwargs)\n",
      "  File \"/Users/Me/anaconda/envs/PythonData/lib/python3.6/site-packages/requests_toolbelt/threaded/thread.py\", line 45, in _make_request\n",
      "    self._handle_request(kwargs)\n",
      "  File \"/Users/Me/anaconda/envs/PythonData/lib/python3.6/site-packages/requests_toolbelt/threaded/thread.py\", line 32, in _handle_request\n",
      "    self._exceptions.put((kwargs, e))\n",
      "AttributeError: 'SessionThread' object has no attribute '_exceptions'\n",
      "\n",
      "\n"
     ]
    },
    {
     "name": "stderr",
     "output_type": "stream",
     "text": [
      "Exception in thread 51d292c6-4cf9-4f00-baf6-899b85953c41:\n",
      "Traceback (most recent call last):\n",
      "  File \"/Users/Me/anaconda/envs/PythonData/lib/python3.6/site-packages/requests_toolbelt/threaded/thread.py\", line 30, in _handle_request\n",
      "    response = self._session.request(**kwargs)\n",
      "  File \"/Users/Me/anaconda/envs/PythonData/lib/python3.6/site-packages/requests/sessions.py\", line 504, in request\n",
      "    prep = self.prepare_request(req)\n",
      "  File \"/Users/Me/anaconda/envs/PythonData/lib/python3.6/site-packages/requests/sessions.py\", line 436, in prepare_request\n",
      "    hooks=merge_hooks(request.hooks, self.hooks),\n",
      "  File \"/Users/Me/anaconda/envs/PythonData/lib/python3.6/site-packages/requests/models.py\", line 302, in prepare\n",
      "    self.prepare_url(url, params)\n",
      "  File \"/Users/Me/anaconda/envs/PythonData/lib/python3.6/site-packages/requests/models.py\", line 382, in prepare_url\n",
      "    raise MissingSchema(error)\n",
      "requests.exceptions.MissingSchema: Invalid URL 'statuses': No schema supplied. Perhaps you meant http://statuses?\n",
      "\n",
      "During handling of the above exception, another exception occurred:\n",
      "\n",
      "Traceback (most recent call last):\n",
      "  File \"/Users/Me/anaconda/envs/PythonData/lib/python3.6/threading.py\", line 916, in _bootstrap_inner\n",
      "    self.run()\n",
      "  File \"/Users/Me/anaconda/envs/PythonData/lib/python3.6/threading.py\", line 864, in run\n",
      "    self._target(*self._args, **self._kwargs)\n",
      "  File \"/Users/Me/anaconda/envs/PythonData/lib/python3.6/site-packages/requests_toolbelt/threaded/thread.py\", line 45, in _make_request\n",
      "    self._handle_request(kwargs)\n",
      "  File \"/Users/Me/anaconda/envs/PythonData/lib/python3.6/site-packages/requests_toolbelt/threaded/thread.py\", line 32, in _handle_request\n",
      "    self._exceptions.put((kwargs, e))\n",
      "AttributeError: 'SessionThread' object has no attribute '_exceptions'\n",
      "\n",
      "Exception in thread 191d16e6-5797-400c-8f4f-4a9ca11e9a88:\n",
      "Traceback (most recent call last):\n",
      "  File \"/Users/Me/anaconda/envs/PythonData/lib/python3.6/site-packages/requests_toolbelt/threaded/thread.py\", line 30, in _handle_request\n",
      "    response = self._session.request(**kwargs)\n",
      "  File \"/Users/Me/anaconda/envs/PythonData/lib/python3.6/site-packages/requests/sessions.py\", line 504, in request\n",
      "    prep = self.prepare_request(req)\n",
      "  File \"/Users/Me/anaconda/envs/PythonData/lib/python3.6/site-packages/requests/sessions.py\", line 436, in prepare_request\n",
      "    hooks=merge_hooks(request.hooks, self.hooks),\n",
      "  File \"/Users/Me/anaconda/envs/PythonData/lib/python3.6/site-packages/requests/models.py\", line 302, in prepare\n",
      "    self.prepare_url(url, params)\n",
      "  File \"/Users/Me/anaconda/envs/PythonData/lib/python3.6/site-packages/requests/models.py\", line 382, in prepare_url\n",
      "    raise MissingSchema(error)\n",
      "requests.exceptions.MissingSchema: Invalid URL 'search_metadata': No schema supplied. Perhaps you meant http://search_metadata?\n",
      "\n",
      "During handling of the above exception, another exception occurred:\n",
      "\n",
      "Traceback (most recent call last):\n",
      "  File \"/Users/Me/anaconda/envs/PythonData/lib/python3.6/threading.py\", line 916, in _bootstrap_inner\n",
      "    self.run()\n",
      "  File \"/Users/Me/anaconda/envs/PythonData/lib/python3.6/threading.py\", line 864, in run\n",
      "    self._target(*self._args, **self._kwargs)\n",
      "  File \"/Users/Me/anaconda/envs/PythonData/lib/python3.6/site-packages/requests_toolbelt/threaded/thread.py\", line 45, in _make_request\n",
      "    self._handle_request(kwargs)\n",
      "  File \"/Users/Me/anaconda/envs/PythonData/lib/python3.6/site-packages/requests_toolbelt/threaded/thread.py\", line 32, in _handle_request\n",
      "    self._exceptions.put((kwargs, e))\n",
      "AttributeError: 'SessionThread' object has no attribute '_exceptions'\n",
      "\n",
      "Exception in thread ada0b948-dea2-4e3d-9f19-fb81fb2fdb48:\n",
      "Traceback (most recent call last):\n",
      "  File \"/Users/Me/anaconda/envs/PythonData/lib/python3.6/site-packages/requests_toolbelt/threaded/thread.py\", line 30, in _handle_request\n",
      "    response = self._session.request(**kwargs)\n",
      "  File \"/Users/Me/anaconda/envs/PythonData/lib/python3.6/site-packages/requests/sessions.py\", line 504, in request\n",
      "    prep = self.prepare_request(req)\n",
      "  File \"/Users/Me/anaconda/envs/PythonData/lib/python3.6/site-packages/requests/sessions.py\", line 436, in prepare_request\n",
      "    hooks=merge_hooks(request.hooks, self.hooks),\n",
      "  File \"/Users/Me/anaconda/envs/PythonData/lib/python3.6/site-packages/requests/models.py\", line 302, in prepare\n",
      "    self.prepare_url(url, params)\n",
      "  File \"/Users/Me/anaconda/envs/PythonData/lib/python3.6/site-packages/requests/models.py\", line 382, in prepare_url\n",
      "    raise MissingSchema(error)\n",
      "requests.exceptions.MissingSchema: Invalid URL 'statuses': No schema supplied. Perhaps you meant http://statuses?\n",
      "\n",
      "During handling of the above exception, another exception occurred:\n",
      "\n",
      "Traceback (most recent call last):\n",
      "  File \"/Users/Me/anaconda/envs/PythonData/lib/python3.6/threading.py\", line 916, in _bootstrap_inner\n",
      "    self.run()\n",
      "  File \"/Users/Me/anaconda/envs/PythonData/lib/python3.6/threading.py\", line 864, in run\n",
      "    self._target(*self._args, **self._kwargs)\n",
      "  File \"/Users/Me/anaconda/envs/PythonData/lib/python3.6/site-packages/requests_toolbelt/threaded/thread.py\", line 45, in _make_request\n",
      "    self._handle_request(kwargs)\n",
      "  File \"/Users/Me/anaconda/envs/PythonData/lib/python3.6/site-packages/requests_toolbelt/threaded/thread.py\", line 32, in _handle_request\n",
      "    self._exceptions.put((kwargs, e))\n",
      "AttributeError: 'SessionThread' object has no attribute '_exceptions'\n",
      "\n",
      "Exception in thread 9ff28ad4-bd48-424b-b71e-cc92cfa729e5:\n",
      "Traceback (most recent call last):\n",
      "  File \"/Users/Me/anaconda/envs/PythonData/lib/python3.6/site-packages/requests_toolbelt/threaded/thread.py\", line 30, in _handle_request\n",
      "    response = self._session.request(**kwargs)\n",
      "  File \"/Users/Me/anaconda/envs/PythonData/lib/python3.6/site-packages/requests/sessions.py\", line 504, in request\n",
      "    prep = self.prepare_request(req)\n",
      "  File \"/Users/Me/anaconda/envs/PythonData/lib/python3.6/site-packages/requests/sessions.py\", line 436, in prepare_request\n",
      "    hooks=merge_hooks(request.hooks, self.hooks),\n",
      "  File \"/Users/Me/anaconda/envs/PythonData/lib/python3.6/site-packages/requests/models.py\", line 302, in prepare\n",
      "    self.prepare_url(url, params)\n",
      "  File \"/Users/Me/anaconda/envs/PythonData/lib/python3.6/site-packages/requests/models.py\", line 382, in prepare_url\n",
      "    raise MissingSchema(error)\n",
      "requests.exceptions.MissingSchema: Invalid URL 'search_metadata': No schema supplied. Perhaps you meant http://search_metadata?\n",
      "\n",
      "During handling of the above exception, another exception occurred:\n",
      "\n",
      "Traceback (most recent call last):\n",
      "  File \"/Users/Me/anaconda/envs/PythonData/lib/python3.6/threading.py\", line 916, in _bootstrap_inner\n",
      "    self.run()\n",
      "  File \"/Users/Me/anaconda/envs/PythonData/lib/python3.6/threading.py\", line 864, in run\n",
      "    self._target(*self._args, **self._kwargs)\n",
      "  File \"/Users/Me/anaconda/envs/PythonData/lib/python3.6/site-packages/requests_toolbelt/threaded/thread.py\", line 45, in _make_request\n",
      "    self._handle_request(kwargs)\n",
      "  File \"/Users/Me/anaconda/envs/PythonData/lib/python3.6/site-packages/requests_toolbelt/threaded/thread.py\", line 32, in _handle_request\n",
      "    self._exceptions.put((kwargs, e))\n",
      "AttributeError: 'SessionThread' object has no attribute '_exceptions'\n",
      "\n",
      "Exception in thread e2236f03-1cc0-42d6-a205-e6c8ec0ff4fb:\n",
      "Traceback (most recent call last):\n",
      "  File \"/Users/Me/anaconda/envs/PythonData/lib/python3.6/site-packages/requests_toolbelt/threaded/thread.py\", line 30, in _handle_request\n",
      "    response = self._session.request(**kwargs)\n",
      "  File \"/Users/Me/anaconda/envs/PythonData/lib/python3.6/site-packages/requests/sessions.py\", line 504, in request\n",
      "    prep = self.prepare_request(req)\n",
      "  File \"/Users/Me/anaconda/envs/PythonData/lib/python3.6/site-packages/requests/sessions.py\", line 436, in prepare_request\n",
      "    hooks=merge_hooks(request.hooks, self.hooks),\n",
      "  File \"/Users/Me/anaconda/envs/PythonData/lib/python3.6/site-packages/requests/models.py\", line 302, in prepare\n",
      "    self.prepare_url(url, params)\n",
      "  File \"/Users/Me/anaconda/envs/PythonData/lib/python3.6/site-packages/requests/models.py\", line 382, in prepare_url\n",
      "    raise MissingSchema(error)\n",
      "requests.exceptions.MissingSchema: Invalid URL 'statuses': No schema supplied. Perhaps you meant http://statuses?\n",
      "\n",
      "During handling of the above exception, another exception occurred:\n",
      "\n",
      "Traceback (most recent call last):\n",
      "  File \"/Users/Me/anaconda/envs/PythonData/lib/python3.6/threading.py\", line 916, in _bootstrap_inner\n",
      "    self.run()\n",
      "  File \"/Users/Me/anaconda/envs/PythonData/lib/python3.6/threading.py\", line 864, in run\n",
      "    self._target(*self._args, **self._kwargs)\n",
      "  File \"/Users/Me/anaconda/envs/PythonData/lib/python3.6/site-packages/requests_toolbelt/threaded/thread.py\", line 45, in _make_request\n",
      "    self._handle_request(kwargs)\n",
      "  File \"/Users/Me/anaconda/envs/PythonData/lib/python3.6/site-packages/requests_toolbelt/threaded/thread.py\", line 32, in _handle_request\n",
      "    self._exceptions.put((kwargs, e))\n",
      "AttributeError: 'SessionThread' object has no attribute '_exceptions'\n",
      "\n",
      "Exception in thread 49b3819f-a8b1-48b6-845c-35de4e059c6d:\n",
      "Traceback (most recent call last):\n",
      "  File \"/Users/Me/anaconda/envs/PythonData/lib/python3.6/site-packages/requests_toolbelt/threaded/thread.py\", line 30, in _handle_request\n",
      "    response = self._session.request(**kwargs)\n",
      "  File \"/Users/Me/anaconda/envs/PythonData/lib/python3.6/site-packages/requests/sessions.py\", line 504, in request\n",
      "    prep = self.prepare_request(req)\n",
      "  File \"/Users/Me/anaconda/envs/PythonData/lib/python3.6/site-packages/requests/sessions.py\", line 436, in prepare_request\n",
      "    hooks=merge_hooks(request.hooks, self.hooks),\n",
      "  File \"/Users/Me/anaconda/envs/PythonData/lib/python3.6/site-packages/requests/models.py\", line 302, in prepare\n",
      "    self.prepare_url(url, params)\n",
      "  File \"/Users/Me/anaconda/envs/PythonData/lib/python3.6/site-packages/requests/models.py\", line 382, in prepare_url\n",
      "    raise MissingSchema(error)\n",
      "requests.exceptions.MissingSchema: Invalid URL 'search_metadata': No schema supplied. Perhaps you meant http://search_metadata?\n",
      "\n",
      "During handling of the above exception, another exception occurred:\n",
      "\n",
      "Traceback (most recent call last):\n",
      "  File \"/Users/Me/anaconda/envs/PythonData/lib/python3.6/threading.py\", line 916, in _bootstrap_inner\n",
      "    self.run()\n",
      "  File \"/Users/Me/anaconda/envs/PythonData/lib/python3.6/threading.py\", line 864, in run\n",
      "    self._target(*self._args, **self._kwargs)\n",
      "  File \"/Users/Me/anaconda/envs/PythonData/lib/python3.6/site-packages/requests_toolbelt/threaded/thread.py\", line 45, in _make_request\n",
      "    self._handle_request(kwargs)\n",
      "  File \"/Users/Me/anaconda/envs/PythonData/lib/python3.6/site-packages/requests_toolbelt/threaded/thread.py\", line 32, in _handle_request\n",
      "    self._exceptions.put((kwargs, e))\n",
      "AttributeError: 'SessionThread' object has no attribute '_exceptions'\n",
      "\n"
     ]
    },
    {
     "name": "stderr",
     "output_type": "stream",
     "text": [
      "Exception in thread 9ad67967-89b6-4cb1-9b2d-3c4d874747db:\n",
      "Traceback (most recent call last):\n",
      "  File \"/Users/Me/anaconda/envs/PythonData/lib/python3.6/site-packages/requests_toolbelt/threaded/thread.py\", line 30, in _handle_request\n",
      "    response = self._session.request(**kwargs)\n",
      "  File \"/Users/Me/anaconda/envs/PythonData/lib/python3.6/site-packages/requests/sessions.py\", line 504, in request\n",
      "    prep = self.prepare_request(req)\n",
      "  File \"/Users/Me/anaconda/envs/PythonData/lib/python3.6/site-packages/requests/sessions.py\", line 436, in prepare_request\n",
      "    hooks=merge_hooks(request.hooks, self.hooks),\n",
      "  File \"/Users/Me/anaconda/envs/PythonData/lib/python3.6/site-packages/requests/models.py\", line 302, in prepare\n",
      "    self.prepare_url(url, params)\n",
      "  File \"/Users/Me/anaconda/envs/PythonData/lib/python3.6/site-packages/requests/models.py\", line 382, in prepare_url\n",
      "    raise MissingSchema(error)\n",
      "requests.exceptions.MissingSchema: Invalid URL 'statuses': No schema supplied. Perhaps you meant http://statuses?\n",
      "\n",
      "During handling of the above exception, another exception occurred:\n",
      "\n",
      "Traceback (most recent call last):\n",
      "  File \"/Users/Me/anaconda/envs/PythonData/lib/python3.6/threading.py\", line 916, in _bootstrap_inner\n",
      "    self.run()\n",
      "  File \"/Users/Me/anaconda/envs/PythonData/lib/python3.6/threading.py\", line 864, in run\n",
      "    self._target(*self._args, **self._kwargs)\n",
      "  File \"/Users/Me/anaconda/envs/PythonData/lib/python3.6/site-packages/requests_toolbelt/threaded/thread.py\", line 45, in _make_request\n",
      "    self._handle_request(kwargs)\n",
      "  File \"/Users/Me/anaconda/envs/PythonData/lib/python3.6/site-packages/requests_toolbelt/threaded/thread.py\", line 32, in _handle_request\n",
      "    self._exceptions.put((kwargs, e))\n",
      "AttributeError: 'SessionThread' object has no attribute '_exceptions'\n",
      "\n",
      "Exception in thread ca06ca10-d3b6-4dff-920d-c751e396df31:\n",
      "Traceback (most recent call last):\n",
      "  File \"/Users/Me/anaconda/envs/PythonData/lib/python3.6/site-packages/requests_toolbelt/threaded/thread.py\", line 30, in _handle_request\n",
      "    response = self._session.request(**kwargs)\n",
      "  File \"/Users/Me/anaconda/envs/PythonData/lib/python3.6/site-packages/requests/sessions.py\", line 504, in request\n",
      "    prep = self.prepare_request(req)\n",
      "  File \"/Users/Me/anaconda/envs/PythonData/lib/python3.6/site-packages/requests/sessions.py\", line 436, in prepare_request\n",
      "    hooks=merge_hooks(request.hooks, self.hooks),\n",
      "  File \"/Users/Me/anaconda/envs/PythonData/lib/python3.6/site-packages/requests/models.py\", line 302, in prepare\n",
      "    self.prepare_url(url, params)\n",
      "  File \"/Users/Me/anaconda/envs/PythonData/lib/python3.6/site-packages/requests/models.py\", line 382, in prepare_url\n",
      "    raise MissingSchema(error)\n",
      "requests.exceptions.MissingSchema: Invalid URL 'search_metadata': No schema supplied. Perhaps you meant http://search_metadata?\n",
      "\n",
      "During handling of the above exception, another exception occurred:\n",
      "\n",
      "Traceback (most recent call last):\n",
      "  File \"/Users/Me/anaconda/envs/PythonData/lib/python3.6/threading.py\", line 916, in _bootstrap_inner\n",
      "    self.run()\n",
      "  File \"/Users/Me/anaconda/envs/PythonData/lib/python3.6/threading.py\", line 864, in run\n",
      "    self._target(*self._args, **self._kwargs)\n",
      "  File \"/Users/Me/anaconda/envs/PythonData/lib/python3.6/site-packages/requests_toolbelt/threaded/thread.py\", line 45, in _make_request\n",
      "    self._handle_request(kwargs)\n",
      "  File \"/Users/Me/anaconda/envs/PythonData/lib/python3.6/site-packages/requests_toolbelt/threaded/thread.py\", line 32, in _handle_request\n",
      "    self._exceptions.put((kwargs, e))\n",
      "AttributeError: 'SessionThread' object has no attribute '_exceptions'\n",
      "\n",
      "Exception in thread 6ad1d40e-4b73-45dd-b14f-ff8144eee67c:\n",
      "Traceback (most recent call last):\n",
      "  File \"/Users/Me/anaconda/envs/PythonData/lib/python3.6/site-packages/requests_toolbelt/threaded/thread.py\", line 30, in _handle_request\n",
      "    response = self._session.request(**kwargs)\n",
      "  File \"/Users/Me/anaconda/envs/PythonData/lib/python3.6/site-packages/requests/sessions.py\", line 504, in request\n",
      "    prep = self.prepare_request(req)\n",
      "  File \"/Users/Me/anaconda/envs/PythonData/lib/python3.6/site-packages/requests/sessions.py\", line 436, in prepare_request\n",
      "    hooks=merge_hooks(request.hooks, self.hooks),\n",
      "  File \"/Users/Me/anaconda/envs/PythonData/lib/python3.6/site-packages/requests/models.py\", line 302, in prepare\n",
      "    self.prepare_url(url, params)\n",
      "  File \"/Users/Me/anaconda/envs/PythonData/lib/python3.6/site-packages/requests/models.py\", line 382, in prepare_url\n",
      "    raise MissingSchema(error)\n",
      "requests.exceptions.MissingSchema: Invalid URL 'statuses': No schema supplied. Perhaps you meant http://statuses?\n",
      "\n",
      "During handling of the above exception, another exception occurred:\n",
      "\n",
      "Traceback (most recent call last):\n",
      "  File \"/Users/Me/anaconda/envs/PythonData/lib/python3.6/threading.py\", line 916, in _bootstrap_inner\n",
      "    self.run()\n",
      "  File \"/Users/Me/anaconda/envs/PythonData/lib/python3.6/threading.py\", line 864, in run\n",
      "    self._target(*self._args, **self._kwargs)\n",
      "  File \"/Users/Me/anaconda/envs/PythonData/lib/python3.6/site-packages/requests_toolbelt/threaded/thread.py\", line 45, in _make_request\n",
      "    self._handle_request(kwargs)\n",
      "  File \"/Users/Me/anaconda/envs/PythonData/lib/python3.6/site-packages/requests_toolbelt/threaded/thread.py\", line 32, in _handle_request\n",
      "    self._exceptions.put((kwargs, e))\n",
      "AttributeError: 'SessionThread' object has no attribute '_exceptions'\n",
      "\n",
      "Exception in thread f8e04cac-40d9-45d7-9c3c-15db6b632f1a:\n",
      "Traceback (most recent call last):\n",
      "  File \"/Users/Me/anaconda/envs/PythonData/lib/python3.6/site-packages/requests_toolbelt/threaded/thread.py\", line 30, in _handle_request\n",
      "    response = self._session.request(**kwargs)\n",
      "  File \"/Users/Me/anaconda/envs/PythonData/lib/python3.6/site-packages/requests/sessions.py\", line 504, in request\n",
      "    prep = self.prepare_request(req)\n",
      "  File \"/Users/Me/anaconda/envs/PythonData/lib/python3.6/site-packages/requests/sessions.py\", line 436, in prepare_request\n",
      "    hooks=merge_hooks(request.hooks, self.hooks),\n",
      "  File \"/Users/Me/anaconda/envs/PythonData/lib/python3.6/site-packages/requests/models.py\", line 302, in prepare\n",
      "    self.prepare_url(url, params)\n",
      "  File \"/Users/Me/anaconda/envs/PythonData/lib/python3.6/site-packages/requests/models.py\", line 382, in prepare_url\n",
      "    raise MissingSchema(error)\n",
      "requests.exceptions.MissingSchema: Invalid URL 'search_metadata': No schema supplied. Perhaps you meant http://search_metadata?\n",
      "\n",
      "During handling of the above exception, another exception occurred:\n",
      "\n",
      "Traceback (most recent call last):\n",
      "  File \"/Users/Me/anaconda/envs/PythonData/lib/python3.6/threading.py\", line 916, in _bootstrap_inner\n",
      "    self.run()\n",
      "  File \"/Users/Me/anaconda/envs/PythonData/lib/python3.6/threading.py\", line 864, in run\n",
      "    self._target(*self._args, **self._kwargs)\n",
      "  File \"/Users/Me/anaconda/envs/PythonData/lib/python3.6/site-packages/requests_toolbelt/threaded/thread.py\", line 45, in _make_request\n",
      "    self._handle_request(kwargs)\n",
      "  File \"/Users/Me/anaconda/envs/PythonData/lib/python3.6/site-packages/requests_toolbelt/threaded/thread.py\", line 32, in _handle_request\n",
      "    self._exceptions.put((kwargs, e))\n",
      "AttributeError: 'SessionThread' object has no attribute '_exceptions'\n",
      "\n"
     ]
    }
   ],
   "source": [
    "# Loop through DataFrame for each Latitude and Longitude\n",
    "k = 0\n",
    "for index, row in base_data_state.iterrows():    \n",
    "    \n",
    "    # Get Tweets for all locations\n",
    "    location = \"%s,%s,100mi\" % (row[\"lat\"], row[\"lon\"])\n",
    "    p = pool.Pool.from_urls(api.search(\"\", geocode = location, count=100), num_processes = 100)\n",
    "    p.join_all()\n",
    "#     public_tweets = api.search(\"\", geocode = location, count=100)\n",
    "    \n",
    "    # Extract all hashtags from tweets directed to the account\n",
    "#     for tweet in public_tweets[\"statuses\"]:\n",
    "\n",
    "#         # Print tweet in JSON\n",
    "#         # print(json.dumps(tweet, sort_keys=True, indent=4, separators=(',', ': ')))\n",
    "\n",
    "#         # Print the Tweet Text         \n",
    "#         print(tweet[\"text\"])\n",
    "\n",
    "#         # Print tweet text\n",
    "#         tweet_df.set_value(k, \"state\", row[\"State\"])\n",
    "#         tweet_df.set_value(k, \"text\", tweet[\"text\"])\n",
    "#         tweet_df.set_value(k, \"lat\", row[\"lat\"])\n",
    "#         tweet_df.set_value(k, \"lon\", row[\"lon\"])\n",
    "\n",
    "#         tweet_df.set_value(k, \"followers\", tweet[\"user\"][\"followers_count\"])\n",
    "#         tweet_df.set_value(k, \"favorites\", tweet[\"user\"][\"favourites_count\"])\n",
    "#         tweet_df.set_value(k, \"friends\", tweet[\"user\"][\"friends_count\"])\n",
    "#         tweet_df.set_value(k, \"statuses_count\", tweet[\"user\"][\"statuses_count\"])\n",
    "\n",
    "#         # Save to a csv for every state\n",
    "#         tweet_df.to_csv(\"Tweet_Dump3.csv\")\n",
    "        \n",
    "#         k = k + 1\n",
    "         "
   ]
  },
  {
   "cell_type": "code",
   "execution_count": 18,
   "metadata": {
    "collapsed": true
   },
   "outputs": [],
   "source": [
    "# We're going to store the tweets inside a dataframe associated with the state, location, and in-belt/out-belt "
   ]
  },
  {
   "cell_type": "code",
   "execution_count": 19,
   "metadata": {
    "collapsed": true
   },
   "outputs": [],
   "source": [
    "# We're going to process all the tweets"
   ]
  },
  {
   "cell_type": "code",
   "execution_count": 20,
   "metadata": {
    "collapsed": true
   },
   "outputs": [],
   "source": [
    "# We're going to group the data in-belt/out-belt"
   ]
  }
 ],
 "metadata": {
  "kernelspec": {
   "display_name": "Python [conda env:PythonData]",
   "language": "python",
   "name": "conda-env-PythonData-py"
  },
  "language_info": {
   "codemirror_mode": {
    "name": "ipython",
    "version": 3
   },
   "file_extension": ".py",
   "mimetype": "text/x-python",
   "name": "python",
   "nbconvert_exporter": "python",
   "pygments_lexer": "ipython3",
   "version": "3.6.1"
  }
 },
 "nbformat": 4,
 "nbformat_minor": 2
}
